[rospy.client][INFO] 2020-11-24 07:56:05,581: init_node, name[/train_4710_1606204565552], pid[4710]
[xmlrpc][INFO] 2020-11-24 07:56:05,581: XML-RPC server binding to 0.0.0.0:0
[xmlrpc][INFO] 2020-11-24 07:56:05,582: Started XML-RPC server [http://192.168.0.191:41415/]
[rospy.init][INFO] 2020-11-24 07:56:05,582: ROS Slave URI: [http://192.168.0.191:41415/]
[rospy.impl.masterslave][INFO] 2020-11-24 07:56:05,582: _ready: http://192.168.0.191:41415/
[rospy.registration][INFO] 2020-11-24 07:56:05,583: Registering with master node http://192.168.0.201:11311
[xmlrpc][INFO] 2020-11-24 07:56:05,584: xml rpc node: starting XML-RPC server
[rospy.init][INFO] 2020-11-24 07:56:05,683: registered with master
[rospy.rosout][INFO] 2020-11-24 07:56:05,683: initializing /rosout core topic
[rospy.rosout][INFO] 2020-11-24 07:56:05,688: connected to core topic /rosout
[rospy.simtime][INFO] 2020-11-24 07:56:05,689: /use_sim_time is not set, will not subscribe to simulated time [/clock] topic
[rospy.internal][INFO] 2020-11-24 07:56:05,713: topic[/bev/flow_image] adding connection to [http://192.168.0.201:37615/], count 0
[rospy.internal][INFO] 2020-11-24 07:56:05,718: topic[/scan] adding connection to [http://192.168.0.201:33433/], count 0
[rospy.internal][INFO] 2020-11-24 07:56:05,722: topic[/start_goal_points] adding connection to [http://192.168.0.201:38933/], count 0
[rospy.internal][INFO] 2020-11-24 07:56:05,723: topic[/scan] adding connection to [http://192.168.0.201:41039/], count 1
[rospy.internal][INFO] 2020-11-24 07:56:05,725: topic[/bev/occupancy_image] adding connection to [http://192.168.0.201:37615/], count 0
[rospy.internal][INFO] 2020-11-24 07:56:05,726: topic[/odom] adding connection to [http://192.168.0.201:41039/], count 0
[rospy.internal][INFO] 2020-11-24 07:56:05,933: topic[/cmd_vel] adding connection to [/bev_flow_estimator], count 0
[rospy.internal][INFO] 2020-11-24 07:56:05,934: topic[/cmd_vel] adding connection to [/gazebo], count 1
[rospy.internal][INFO] 2020-11-24 07:56:05,935: topic[/rosout] adding connection to [/rosout], count 0
[rospy.internal][INFO] 2020-11-24 07:56:05,936: topic[/is_finish_episode] adding connection to [/episode_manager], count 0
[rospy.internal][ERROR] 2020-11-24 07:56:08,568: Unable to initiate TCP/IP socket to 192.168.0.201:43621 (http://192.168.0.201:41039/): Traceback (most recent call last):
  File "/opt/ros/noetic/lib/python3/dist-packages/rospy/impl/tcpros_base.py", line 562, in connect
    self.read_header()
  File "/opt/ros/noetic/lib/python3/dist-packages/rospy/impl/tcpros_base.py", line 657, in read_header
    self._validate_header(read_ros_handshake_header(sock, self.read_buff, self.protocol.buff_size))
  File "/opt/ros/noetic/lib/python3/dist-packages/rospy/impl/tcpros_base.py", line 600, in _validate_header
    raise TransportInitError("remote error reported: %s"%header['error'])
rospy.exceptions.TransportInitError: remote error reported: received a connection for a nonexistent topic [/scan] from [TCPROS connection on port 43621 to [192.168.0.191:52912 on socket 185]] [/train_4710_1606204565552].

[rospy.internal][ERROR] 2020-11-24 07:56:08,803: Unable to initiate TCP/IP socket to 192.168.0.201:43621 (http://192.168.0.201:41039/): Traceback (most recent call last):
  File "/opt/ros/noetic/lib/python3/dist-packages/rospy/impl/tcpros_base.py", line 562, in connect
    self.read_header()
  File "/opt/ros/noetic/lib/python3/dist-packages/rospy/impl/tcpros_base.py", line 657, in read_header
    self._validate_header(read_ros_handshake_header(sock, self.read_buff, self.protocol.buff_size))
  File "/opt/ros/noetic/lib/python3/dist-packages/rospy/impl/tcpros_base.py", line 600, in _validate_header
    raise TransportInitError("remote error reported: %s"%header['error'])
rospy.exceptions.TransportInitError: remote error reported: received a connection for a nonexistent topic [/odom] from [TCPROS connection on port 43621 to [192.168.0.191:52914 on socket 185]] [/train_4710_1606204565552].

[rospy.internal][INFO] 2020-11-24 07:56:09,150: topic[/cmd_vel] removing connection to /gazebo
[rospy.internal][ERROR] 2020-11-24 07:56:09,571: Unable to initiate TCP/IP socket to 192.168.0.201:43621 (http://192.168.0.201:41039/): Traceback (most recent call last):
  File "/opt/ros/noetic/lib/python3/dist-packages/rospy/impl/tcpros_base.py", line 562, in connect
    self.read_header()
  File "/opt/ros/noetic/lib/python3/dist-packages/rospy/impl/tcpros_base.py", line 657, in read_header
    self._validate_header(read_ros_handshake_header(sock, self.read_buff, self.protocol.buff_size))
  File "/opt/ros/noetic/lib/python3/dist-packages/rospy/impl/tcpros_base.py", line 600, in _validate_header
    raise TransportInitError("remote error reported: %s"%header['error'])
rospy.exceptions.TransportInitError: remote error reported: received a connection for a nonexistent topic [/scan] from [TCPROS connection on port 43621 to [192.168.0.191:52916 on socket 148]] [/train_4710_1606204565552].

[rospy.internal][ERROR] 2020-11-24 07:56:09,805: Unable to initiate TCP/IP socket to 192.168.0.201:43621 (http://192.168.0.201:41039/): Traceback (most recent call last):
  File "/opt/ros/noetic/lib/python3/dist-packages/rospy/impl/tcpros_base.py", line 562, in connect
    self.read_header()
  File "/opt/ros/noetic/lib/python3/dist-packages/rospy/impl/tcpros_base.py", line 657, in read_header
    self._validate_header(read_ros_handshake_header(sock, self.read_buff, self.protocol.buff_size))
  File "/opt/ros/noetic/lib/python3/dist-packages/rospy/impl/tcpros_base.py", line 600, in _validate_header
    raise TransportInitError("remote error reported: %s"%header['error'])
rospy.exceptions.TransportInitError: remote error reported: received a connection for a nonexistent topic [/odom] from [TCPROS connection on port 43621 to [192.168.0.191:52918 on socket 188]] [/train_4710_1606204565552].

[rospy.internal][ERROR] 2020-11-24 07:56:11,575: Unable to initiate TCP/IP socket to 192.168.0.201:43621 (http://192.168.0.201:41039/): Traceback (most recent call last):
  File "/opt/ros/noetic/lib/python3/dist-packages/rospy/impl/tcpros_base.py", line 562, in connect
    self.read_header()
  File "/opt/ros/noetic/lib/python3/dist-packages/rospy/impl/tcpros_base.py", line 657, in read_header
    self._validate_header(read_ros_handshake_header(sock, self.read_buff, self.protocol.buff_size))
  File "/opt/ros/noetic/lib/python3/dist-packages/rospy/impl/tcpros_base.py", line 600, in _validate_header
    raise TransportInitError("remote error reported: %s"%header['error'])
rospy.exceptions.TransportInitError: remote error reported: received a connection for a nonexistent topic [/scan] from [TCPROS connection on port 43621 to [192.168.0.191:52920 on socket 114]] [/train_4710_1606204565552].

[rospy.internal][ERROR] 2020-11-24 07:56:11,809: Unable to initiate TCP/IP socket to 192.168.0.201:43621 (http://192.168.0.201:41039/): Traceback (most recent call last):
  File "/opt/ros/noetic/lib/python3/dist-packages/rospy/impl/tcpros_base.py", line 562, in connect
    self.read_header()
  File "/opt/ros/noetic/lib/python3/dist-packages/rospy/impl/tcpros_base.py", line 657, in read_header
    self._validate_header(read_ros_handshake_header(sock, self.read_buff, self.protocol.buff_size))
  File "/opt/ros/noetic/lib/python3/dist-packages/rospy/impl/tcpros_base.py", line 600, in _validate_header
    raise TransportInitError("remote error reported: %s"%header['error'])
rospy.exceptions.TransportInitError: remote error reported: received a connection for a nonexistent topic [/odom] from [TCPROS connection on port 43621 to [192.168.0.191:52922 on socket 188]] [/train_4710_1606204565552].

[rospy.internal][ERROR] 2020-11-24 07:56:15,580: Unable to initiate TCP/IP socket to 192.168.0.201:43621 (http://192.168.0.201:41039/): Traceback (most recent call last):
  File "/opt/ros/noetic/lib/python3/dist-packages/rospy/impl/tcpros_base.py", line 562, in connect
    self.read_header()
  File "/opt/ros/noetic/lib/python3/dist-packages/rospy/impl/tcpros_base.py", line 657, in read_header
    self._validate_header(read_ros_handshake_header(sock, self.read_buff, self.protocol.buff_size))
  File "/opt/ros/noetic/lib/python3/dist-packages/rospy/impl/tcpros_base.py", line 600, in _validate_header
    raise TransportInitError("remote error reported: %s"%header['error'])
rospy.exceptions.TransportInitError: remote error reported: received a connection for a nonexistent topic [/scan] from [TCPROS connection on port 43621 to [192.168.0.191:52924 on socket 190]] [/train_4710_1606204565552].

[rospy.internal][ERROR] 2020-11-24 07:56:15,814: Unable to initiate TCP/IP socket to 192.168.0.201:43621 (http://192.168.0.201:41039/): Traceback (most recent call last):
  File "/opt/ros/noetic/lib/python3/dist-packages/rospy/impl/tcpros_base.py", line 562, in connect
    self.read_header()
  File "/opt/ros/noetic/lib/python3/dist-packages/rospy/impl/tcpros_base.py", line 657, in read_header
    self._validate_header(read_ros_handshake_header(sock, self.read_buff, self.protocol.buff_size))
  File "/opt/ros/noetic/lib/python3/dist-packages/rospy/impl/tcpros_base.py", line 600, in _validate_header
    raise TransportInitError("remote error reported: %s"%header['error'])
rospy.exceptions.TransportInitError: remote error reported: received a connection for a nonexistent topic [/odom] from [TCPROS connection on port 43621 to [192.168.0.191:52926 on socket 190]] [/train_4710_1606204565552].

[rospy.internal][ERROR] 2020-11-24 07:56:23,590: Unable to initiate TCP/IP socket to 192.168.0.201:43621 (http://192.168.0.201:41039/): Traceback (most recent call last):
  File "/opt/ros/noetic/lib/python3/dist-packages/rospy/impl/tcpros_base.py", line 562, in connect
    self.read_header()
  File "/opt/ros/noetic/lib/python3/dist-packages/rospy/impl/tcpros_base.py", line 657, in read_header
    self._validate_header(read_ros_handshake_header(sock, self.read_buff, self.protocol.buff_size))
  File "/opt/ros/noetic/lib/python3/dist-packages/rospy/impl/tcpros_base.py", line 600, in _validate_header
    raise TransportInitError("remote error reported: %s"%header['error'])
rospy.exceptions.TransportInitError: remote error reported: received a connection for a nonexistent topic [/scan] from [TCPROS connection on port 43621 to [192.168.0.191:52928 on socket 190]] [/train_4710_1606204565552].

[rospy.internal][ERROR] 2020-11-24 07:56:23,824: Unable to initiate TCP/IP socket to 192.168.0.201:43621 (http://192.168.0.201:41039/): Traceback (most recent call last):
  File "/opt/ros/noetic/lib/python3/dist-packages/rospy/impl/tcpros_base.py", line 562, in connect
    self.read_header()
  File "/opt/ros/noetic/lib/python3/dist-packages/rospy/impl/tcpros_base.py", line 657, in read_header
    self._validate_header(read_ros_handshake_header(sock, self.read_buff, self.protocol.buff_size))
  File "/opt/ros/noetic/lib/python3/dist-packages/rospy/impl/tcpros_base.py", line 600, in _validate_header
    raise TransportInitError("remote error reported: %s"%header['error'])
rospy.exceptions.TransportInitError: remote error reported: received a connection for a nonexistent topic [/odom] from [TCPROS connection on port 43621 to [192.168.0.191:52930 on socket 190]] [/train_4710_1606204565552].

[rospy.internal][INFO] 2020-11-24 07:56:32,258: topic[/cmd_vel] adding connection to [/gazebo], count 1
[rospy.internal][WARNING] 2020-11-24 07:56:48,003: Unknown error initiating TCP/IP socket to 192.168.0.201:58235 (http://192.168.0.201:37615/): Traceback (most recent call last):
  File "/opt/ros/noetic/lib/python3/dist-packages/rospy/impl/tcpros_base.py", line 562, in connect
    self.read_header()
  File "/opt/ros/noetic/lib/python3/dist-packages/rospy/impl/tcpros_base.py", line 657, in read_header
    self._validate_header(read_ros_handshake_header(sock, self.read_buff, self.protocol.buff_size))
  File "/opt/ros/noetic/lib/python3/dist-packages/rosgraph/network.py", line 357, in read_ros_handshake_header
    d = sock.recv(buff_size)
ConnectionResetError: [Errno 104] Connection reset by peer

[rospy.internal][WARNING] 2020-11-24 07:56:48,003: Unknown error initiating TCP/IP socket to 192.168.0.201:58235 (http://192.168.0.201:37615/): Traceback (most recent call last):
  File "/opt/ros/noetic/lib/python3/dist-packages/rospy/impl/tcpros_base.py", line 562, in connect
    self.read_header()
  File "/opt/ros/noetic/lib/python3/dist-packages/rospy/impl/tcpros_base.py", line 657, in read_header
    self._validate_header(read_ros_handshake_header(sock, self.read_buff, self.protocol.buff_size))
  File "/opt/ros/noetic/lib/python3/dist-packages/rosgraph/network.py", line 357, in read_ros_handshake_header
    d = sock.recv(buff_size)
ConnectionResetError: [Errno 104] Connection reset by peer

[rospy.internal][INFO] 2020-11-24 07:56:48,004: topic[/bev/flow_image] removing connection to http://192.168.0.201:37615/
[rospy.internal][INFO] 2020-11-24 07:56:48,004: topic[/bev/occupancy_image] removing connection to http://192.168.0.201:37615/
[rospy.internal][INFO] 2020-11-24 07:56:48,073: topic[/cmd_vel] removing connection to /bev_flow_estimator
[rospy.core][INFO] 2020-11-24 07:58:31,752: signal_shutdown [signal-2]
[rospy.internal][INFO] 2020-11-24 07:58:31,760: topic[/rosout] removing connection to /rosout
[rospy.internal][INFO] 2020-11-24 07:58:31,761: topic[/cmd_vel] removing connection to /gazebo
[rospy.internal][INFO] 2020-11-24 07:58:31,761: topic[/is_finish_episode] removing connection to /episode_manager
[rospy.internal][INFO] 2020-11-24 07:58:31,762: topic[/odom] removing connection to http://192.168.0.201:41039/
[rospy.internal][INFO] 2020-11-24 07:58:31,763: topic[/start_goal_points] removing connection to http://192.168.0.201:38933/
[rospy.internal][WARNING] 2020-11-24 07:58:31,764: Unknown error initiating TCP/IP socket to 192.168.0.201:44215 (http://192.168.0.201:38933/): Traceback (most recent call last):
  File "/opt/ros/noetic/lib/python3/dist-packages/rospy/impl/tcpros_base.py", line 563, in connect
    self.local_endpoint = self.socket.getsockname()
AttributeError: 'NoneType' object has no attribute 'getsockname'

[rospy.internal][INFO] 2020-11-24 07:58:31,765: topic[/scan] removing connection to http://192.168.0.201:33433/
[rospy.internal][INFO] 2020-11-24 07:58:31,765: topic[/scan] removing connection to http://192.168.0.201:41039/
[rospy.impl.masterslave][INFO] 2020-11-24 07:58:31,766: signal-2
[rospy.internal][WARNING] 2020-11-24 07:58:31,766: Unknown error initiating TCP/IP socket to 192.168.0.201:39153 (http://192.168.0.201:33433/): Traceback (most recent call last):
  File "/opt/ros/noetic/lib/python3/dist-packages/rospy/impl/tcpros_base.py", line 562, in connect
    self.read_header()
  File "/opt/ros/noetic/lib/python3/dist-packages/rospy/impl/tcpros_base.py", line 657, in read_header
    self._validate_header(read_ros_handshake_header(sock, self.read_buff, self.protocol.buff_size))
AttributeError: 'NoneType' object has no attribute 'buff_size'

[rospy.core][INFO] 2020-11-24 07:58:32,251: signal_shutdown [signal-2]
[rospy.core][INFO] 2020-11-24 07:58:32,294: signal_shutdown [signal-2]
[rospy.core][INFO] 2020-11-24 07:58:32,313: signal_shutdown [signal-2]
[rospy.core][INFO] 2020-11-24 07:58:32,343: signal_shutdown [signal-2]
[rospy.core][INFO] 2020-11-24 07:58:32,386: signal_shutdown [signal-2]
[rospy.core][INFO] 2020-11-24 07:58:32,411: signal_shutdown [signal-2]
[rospy.core][INFO] 2020-11-24 07:58:32,450: signal_shutdown [signal-2]
[rospy.core][INFO] 2020-11-24 07:58:32,460: signal_shutdown [atexit]
