[rospy.client][INFO] 2020-11-20 12:54:38,084: init_node, name[/train_2763_1605876878052], pid[2763]
[xmlrpc][INFO] 2020-11-20 12:54:38,084: XML-RPC server binding to 0.0.0.0:0
[xmlrpc][INFO] 2020-11-20 12:54:38,085: Started XML-RPC server [http://192.168.0.191:37565/]
[rospy.init][INFO] 2020-11-20 12:54:38,085: ROS Slave URI: [http://192.168.0.191:37565/]
[rospy.impl.masterslave][INFO] 2020-11-20 12:54:38,086: _ready: http://192.168.0.191:37565/
[rospy.registration][INFO] 2020-11-20 12:54:38,087: Registering with master node http://192.168.0.201:11311
[xmlrpc][INFO] 2020-11-20 12:54:38,087: xml rpc node: starting XML-RPC server
[rospy.init][INFO] 2020-11-20 12:54:38,186: registered with master
[rospy.rosout][INFO] 2020-11-20 12:54:38,186: initializing /rosout core topic
[rospy.rosout][INFO] 2020-11-20 12:54:38,192: connected to core topic /rosout
[rospy.simtime][INFO] 2020-11-20 12:54:38,194: /use_sim_time is not set, will not subscribe to simulated time [/clock] topic
[rospy.internal][INFO] 2020-11-20 12:54:38,219: topic[/bev/flow_image] adding connection to [http://192.168.0.201:37547/], count 0
[rospy.internal][INFO] 2020-11-20 12:54:38,222: topic[/scan] adding connection to [http://192.168.0.201:41431/], count 0
[rospy.internal][INFO] 2020-11-20 12:54:38,223: topic[/start_goal_points] adding connection to [http://192.168.0.201:44137/], count 0
[rospy.internal][INFO] 2020-11-20 12:54:38,224: topic[/scan] adding connection to [http://192.168.0.201:36467/], count 0
[rospy.internal][INFO] 2020-11-20 12:54:38,229: topic[/odom] adding connection to [http://192.168.0.201:36467/], count 0
[rospy.internal][INFO] 2020-11-20 12:54:38,231: topic[/bev/occupancy_image] adding connection to [http://192.168.0.201:37547/], count 0
[rosout][ERROR] 2020-11-20 12:54:38,426: bad callback: <bound method ROSNode.laser_callback of <__main__.ROSNode object at 0x7f076494e1f0>>
Traceback (most recent call last):
  File "/opt/ros/noetic/lib/python3/dist-packages/rospy/topics.py", line 750, in _invoke_callback
    cb(msg)
  File "./train.py", line 152, in laser_callback
    print("ROS:scan_data[",i,"] =" ,self.scan_data[i])
IndexError: index 13 is out of bounds for axis 0 with size 5

[rospy.internal][INFO] 2020-11-20 12:54:38,434: topic[/rosout] adding connection to [/rosout], count 0
[rospy.internal][INFO] 2020-11-20 12:54:38,436: topic[/cmd_vel] adding connection to [/bev_flow_estimator], count 0
[rospy.internal][INFO] 2020-11-20 12:54:38,436: topic[/is_created_scenarios] adding connection to [/episode_manager], count 0
[rospy.internal][INFO] 2020-11-20 12:54:38,437: topic[/cmd_vel] adding connection to [/gazebo], count 1
[rosout][ERROR] 2020-11-20 12:54:38,457: bad callback: <bound method ROSNode.laser_callback of <__main__.ROSNode object at 0x7f076494e1f0>>
Traceback (most recent call last):
  File "/opt/ros/noetic/lib/python3/dist-packages/rospy/topics.py", line 750, in _invoke_callback
    cb(msg)
  File "./train.py", line 152, in laser_callback
    print("ROS:scan_data[",i,"] =" ,self.scan_data[i])
IndexError: index 221 is out of bounds for axis 0 with size 6

[rosout][ERROR] 2020-11-20 12:54:38,662: bad callback: <bound method ROSNode.laser_callback of <__main__.ROSNode object at 0x7f076494e1f0>>
Traceback (most recent call last):
  File "/opt/ros/noetic/lib/python3/dist-packages/rospy/topics.py", line 750, in _invoke_callback
    cb(msg)
  File "./train.py", line 152, in laser_callback
    print("ROS:scan_data[",i,"] =" ,self.scan_data[i])
IndexError: index 15 is out of bounds for axis 0 with size 10

[rosout][ERROR] 2020-11-20 12:54:38,693: bad callback: <bound method ROSNode.laser_callback of <__main__.ROSNode object at 0x7f076494e1f0>>
Traceback (most recent call last):
  File "/opt/ros/noetic/lib/python3/dist-packages/rospy/topics.py", line 750, in _invoke_callback
    cb(msg)
  File "./train.py", line 152, in laser_callback
    print("ROS:scan_data[",i,"] =" ,self.scan_data[i])
IndexError: index 225 is out of bounds for axis 0 with size 11

[rosout][ERROR] 2020-11-20 12:54:38,889: bad callback: <bound method ROSNode.laser_callback of <__main__.ROSNode object at 0x7f076494e1f0>>
Traceback (most recent call last):
  File "/opt/ros/noetic/lib/python3/dist-packages/rospy/topics.py", line 750, in _invoke_callback
    cb(msg)
  File "./train.py", line 152, in laser_callback
    print("ROS:scan_data[",i,"] =" ,self.scan_data[i])
IndexError: index 16 is out of bounds for axis 0 with size 15

[rosout][ERROR] 2020-11-20 12:54:38,919: bad callback: <bound method ROSNode.laser_callback of <__main__.ROSNode object at 0x7f076494e1f0>>
Traceback (most recent call last):
  File "/opt/ros/noetic/lib/python3/dist-packages/rospy/topics.py", line 750, in _invoke_callback
    cb(msg)
  File "./train.py", line 152, in laser_callback
    print("ROS:scan_data[",i,"] =" ,self.scan_data[i])
IndexError: index 221 is out of bounds for axis 0 with size 16

[rosout][ERROR] 2020-11-20 12:54:39,116: bad callback: <bound method ROSNode.laser_callback of <__main__.ROSNode object at 0x7f076494e1f0>>
Traceback (most recent call last):
  File "/opt/ros/noetic/lib/python3/dist-packages/rospy/topics.py", line 750, in _invoke_callback
    cb(msg)
  File "./train.py", line 152, in laser_callback
    print("ROS:scan_data[",i,"] =" ,self.scan_data[i])
IndexError: index 39 is out of bounds for axis 0 with size 30

[rosout][ERROR] 2020-11-20 12:54:39,148: bad callback: <bound method ROSNode.laser_callback of <__main__.ROSNode object at 0x7f076494e1f0>>
Traceback (most recent call last):
  File "/opt/ros/noetic/lib/python3/dist-packages/rospy/topics.py", line 750, in _invoke_callback
    cb(msg)
  File "./train.py", line 152, in laser_callback
    print("ROS:scan_data[",i,"] =" ,self.scan_data[i])
IndexError: index 221 is out of bounds for axis 0 with size 31

[rosout][ERROR] 2020-11-20 12:54:39,356: bad callback: <bound method ROSNode.laser_callback of <__main__.ROSNode object at 0x7f076494e1f0>>
Traceback (most recent call last):
  File "/opt/ros/noetic/lib/python3/dist-packages/rospy/topics.py", line 750, in _invoke_callback
    cb(msg)
  File "./train.py", line 152, in laser_callback
    print("ROS:scan_data[",i,"] =" ,self.scan_data[i])
IndexError: index 346 is out of bounds for axis 0 with size 297

[rosout][ERROR] 2020-11-20 12:54:39,386: bad callback: <bound method ROSNode.laser_callback of <__main__.ROSNode object at 0x7f076494e1f0>>
Traceback (most recent call last):
  File "/opt/ros/noetic/lib/python3/dist-packages/rospy/topics.py", line 750, in _invoke_callback
    cb(msg)
  File "./train.py", line 152, in laser_callback
    print("ROS:scan_data[",i,"] =" ,self.scan_data[i])
IndexError: index 323 is out of bounds for axis 0 with size 323

[rospy.core][INFO] 2020-11-20 12:54:40,727: signal_shutdown [atexit]
[rospy.internal][INFO] 2020-11-20 12:54:40,732: topic[/rosout] removing connection to /rosout
[rospy.internal][INFO] 2020-11-20 12:54:40,732: topic[/cmd_vel] removing connection to /bev_flow_estimator
[rospy.internal][INFO] 2020-11-20 12:54:40,732: topic[/cmd_vel] removing connection to /gazebo
[rospy.internal][INFO] 2020-11-20 12:54:40,733: topic[/is_created_scenarios] removing connection to /episode_manager
[rospy.internal][INFO] 2020-11-20 12:54:40,733: topic[/bev/flow_image] removing connection to http://192.168.0.201:37547/
[rospy.internal][INFO] 2020-11-20 12:54:40,734: topic[/bev/occupancy_image] removing connection to http://192.168.0.201:37547/
[rospy.internal][INFO] 2020-11-20 12:54:40,734: topic[/odom] removing connection to http://192.168.0.201:36467/
[rospy.internal][INFO] 2020-11-20 12:54:40,734: topic[/start_goal_points] removing connection to http://192.168.0.201:44137/
[rospy.internal][INFO] 2020-11-20 12:54:40,735: topic[/scan] removing connection to http://192.168.0.201:41431/
[rospy.internal][INFO] 2020-11-20 12:54:40,735: topic[/scan] removing connection to http://192.168.0.201:36467/
[rospy.impl.masterslave][INFO] 2020-11-20 12:54:40,736: atexit
[rospy.internal][WARNING] 2020-11-20 12:54:40,736: Unknown error initiating TCP/IP socket to 192.168.0.201:57757 (http://192.168.0.201:37547/): Traceback (most recent call last):
  File "/opt/ros/noetic/lib/python3/dist-packages/rospy/impl/tcpros_base.py", line 562, in connect
    self.read_header()
  File "/opt/ros/noetic/lib/python3/dist-packages/rospy/impl/tcpros_base.py", line 657, in read_header
    self._validate_header(read_ros_handshake_header(sock, self.read_buff, self.protocol.buff_size))
AttributeError: 'NoneType' object has no attribute 'buff_size'

[rospy.internal][WARNING] 2020-11-20 12:54:40,737: Unknown error initiating TCP/IP socket to 192.168.0.201:44769 (http://192.168.0.201:36467/): Traceback (most recent call last):
  File "/opt/ros/noetic/lib/python3/dist-packages/rospy/impl/tcpros_base.py", line 562, in connect
    self.read_header()
  File "/opt/ros/noetic/lib/python3/dist-packages/rospy/impl/tcpros_base.py", line 657, in read_header
    self._validate_header(read_ros_handshake_header(sock, self.read_buff, self.protocol.buff_size))
AttributeError: 'NoneType' object has no attribute 'buff_size'

