[rospy.client][INFO] 2020-11-24 08:03:31,425: init_node, name[/train_4892_1606205011396], pid[4892]
[xmlrpc][INFO] 2020-11-24 08:03:31,426: XML-RPC server binding to 0.0.0.0:0
[xmlrpc][INFO] 2020-11-24 08:03:31,426: Started XML-RPC server [http://192.168.0.191:46305/]
[rospy.init][INFO] 2020-11-24 08:03:31,426: ROS Slave URI: [http://192.168.0.191:46305/]
[rospy.impl.masterslave][INFO] 2020-11-24 08:03:31,427: _ready: http://192.168.0.191:46305/
[rospy.registration][INFO] 2020-11-24 08:03:31,428: Registering with master node http://192.168.0.201:11311
[xmlrpc][INFO] 2020-11-24 08:03:31,428: xml rpc node: starting XML-RPC server
[rospy.init][INFO] 2020-11-24 08:03:31,527: registered with master
[rospy.rosout][INFO] 2020-11-24 08:03:31,527: initializing /rosout core topic
[rospy.rosout][INFO] 2020-11-24 08:03:31,532: connected to core topic /rosout
[rospy.simtime][INFO] 2020-11-24 08:03:31,534: /use_sim_time is not set, will not subscribe to simulated time [/clock] topic
[rospy.internal][INFO] 2020-11-24 08:03:31,559: topic[/bev/flow_image] adding connection to [http://192.168.0.201:46143/], count 0
[rospy.internal][INFO] 2020-11-24 08:03:31,561: topic[/scan] adding connection to [http://192.168.0.201:37341/], count 0
[rospy.internal][INFO] 2020-11-24 08:03:31,562: topic[/scan] adding connection to [http://192.168.0.201:36253/], count 1
[rospy.internal][INFO] 2020-11-24 08:03:31,565: topic[/start_goal_points] adding connection to [http://192.168.0.201:41539/], count 0
[rospy.internal][INFO] 2020-11-24 08:03:31,567: topic[/odom] adding connection to [http://192.168.0.201:37341/], count 0
[rospy.internal][INFO] 2020-11-24 08:03:31,570: topic[/bev/occupancy_image] adding connection to [http://192.168.0.201:46143/], count 0
[rospy.internal][INFO] 2020-11-24 08:03:31,735: topic[/rosout] adding connection to [/rosout], count 0
[rospy.internal][INFO] 2020-11-24 08:03:31,759: topic[/is_finish_episode] adding connection to [/episode_manager], count 0
[rospy.internal][INFO] 2020-11-24 08:03:31,769: topic[/cmd_vel] adding connection to [/gazebo], count 0
[rospy.internal][INFO] 2020-11-24 08:03:31,772: topic[/cmd_vel] adding connection to [/bev_flow_estimator], count 1
[rospy.internal][ERROR] 2020-11-24 08:03:54,928: Unable to initiate TCP/IP socket to 192.168.0.201:50197 (http://192.168.0.201:37341/): Traceback (most recent call last):
  File "/opt/ros/noetic/lib/python3/dist-packages/rospy/impl/tcpros_base.py", line 562, in connect
    self.read_header()
  File "/opt/ros/noetic/lib/python3/dist-packages/rospy/impl/tcpros_base.py", line 657, in read_header
    self._validate_header(read_ros_handshake_header(sock, self.read_buff, self.protocol.buff_size))
  File "/opt/ros/noetic/lib/python3/dist-packages/rospy/impl/tcpros_base.py", line 600, in _validate_header
    raise TransportInitError("remote error reported: %s"%header['error'])
rospy.exceptions.TransportInitError: remote error reported: received a connection for a nonexistent topic [/scan] from [TCPROS connection on port 50197 to [192.168.0.191:43132 on socket 111]] [/train_4892_1606205011396].

[rospy.internal][ERROR] 2020-11-24 08:03:55,082: Unable to initiate TCP/IP socket to 192.168.0.201:50197 (http://192.168.0.201:37341/): Traceback (most recent call last):
  File "/opt/ros/noetic/lib/python3/dist-packages/rospy/impl/tcpros_base.py", line 562, in connect
    self.read_header()
  File "/opt/ros/noetic/lib/python3/dist-packages/rospy/impl/tcpros_base.py", line 657, in read_header
    self._validate_header(read_ros_handshake_header(sock, self.read_buff, self.protocol.buff_size))
  File "/opt/ros/noetic/lib/python3/dist-packages/rospy/impl/tcpros_base.py", line 600, in _validate_header
    raise TransportInitError("remote error reported: %s"%header['error'])
rospy.exceptions.TransportInitError: remote error reported: received a connection for a nonexistent topic [/odom] from [TCPROS connection on port 50197 to [192.168.0.191:43134 on socket 110]] [/train_4892_1606205011396].

[rospy.internal][INFO] 2020-11-24 08:03:55,490: topic[/cmd_vel] removing connection to /gazebo
[rospy.internal][ERROR] 2020-11-24 08:03:55,931: Unable to initiate TCP/IP socket to 192.168.0.201:50197 (http://192.168.0.201:37341/): Traceback (most recent call last):
  File "/opt/ros/noetic/lib/python3/dist-packages/rospy/impl/tcpros_base.py", line 562, in connect
    self.read_header()
  File "/opt/ros/noetic/lib/python3/dist-packages/rospy/impl/tcpros_base.py", line 657, in read_header
    self._validate_header(read_ros_handshake_header(sock, self.read_buff, self.protocol.buff_size))
  File "/opt/ros/noetic/lib/python3/dist-packages/rospy/impl/tcpros_base.py", line 600, in _validate_header
    raise TransportInitError("remote error reported: %s"%header['error'])
rospy.exceptions.TransportInitError: remote error reported: received a connection for a nonexistent topic [/scan] from [TCPROS connection on port 50197 to [192.168.0.191:43136 on socket 111]] [/train_4892_1606205011396].

[rospy.internal][ERROR] 2020-11-24 08:03:56,085: Unable to initiate TCP/IP socket to 192.168.0.201:50197 (http://192.168.0.201:37341/): Traceback (most recent call last):
  File "/opt/ros/noetic/lib/python3/dist-packages/rospy/impl/tcpros_base.py", line 562, in connect
    self.read_header()
  File "/opt/ros/noetic/lib/python3/dist-packages/rospy/impl/tcpros_base.py", line 657, in read_header
    self._validate_header(read_ros_handshake_header(sock, self.read_buff, self.protocol.buff_size))
  File "/opt/ros/noetic/lib/python3/dist-packages/rospy/impl/tcpros_base.py", line 600, in _validate_header
    raise TransportInitError("remote error reported: %s"%header['error'])
rospy.exceptions.TransportInitError: remote error reported: received a connection for a nonexistent topic [/odom] from [TCPROS connection on port 50197 to [192.168.0.191:43138 on socket 111]] [/train_4892_1606205011396].

[rospy.internal][ERROR] 2020-11-24 08:03:57,935: Unable to initiate TCP/IP socket to 192.168.0.201:50197 (http://192.168.0.201:37341/): Traceback (most recent call last):
  File "/opt/ros/noetic/lib/python3/dist-packages/rospy/impl/tcpros_base.py", line 562, in connect
    self.read_header()
  File "/opt/ros/noetic/lib/python3/dist-packages/rospy/impl/tcpros_base.py", line 657, in read_header
    self._validate_header(read_ros_handshake_header(sock, self.read_buff, self.protocol.buff_size))
  File "/opt/ros/noetic/lib/python3/dist-packages/rospy/impl/tcpros_base.py", line 600, in _validate_header
    raise TransportInitError("remote error reported: %s"%header['error'])
rospy.exceptions.TransportInitError: remote error reported: received a connection for a nonexistent topic [/scan] from [TCPROS connection on port 50197 to [192.168.0.191:43140 on socket 111]] [/train_4892_1606205011396].

[rospy.internal][ERROR] 2020-11-24 08:03:58,088: Unable to initiate TCP/IP socket to 192.168.0.201:50197 (http://192.168.0.201:37341/): Traceback (most recent call last):
  File "/opt/ros/noetic/lib/python3/dist-packages/rospy/impl/tcpros_base.py", line 562, in connect
    self.read_header()
  File "/opt/ros/noetic/lib/python3/dist-packages/rospy/impl/tcpros_base.py", line 657, in read_header
    self._validate_header(read_ros_handshake_header(sock, self.read_buff, self.protocol.buff_size))
  File "/opt/ros/noetic/lib/python3/dist-packages/rospy/impl/tcpros_base.py", line 600, in _validate_header
    raise TransportInitError("remote error reported: %s"%header['error'])
rospy.exceptions.TransportInitError: remote error reported: received a connection for a nonexistent topic [/odom] from [TCPROS connection on port 50197 to [192.168.0.191:43142 on socket 111]] [/train_4892_1606205011396].

[rospy.internal][ERROR] 2020-11-24 08:04:01,940: Unable to initiate TCP/IP socket to 192.168.0.201:50197 (http://192.168.0.201:37341/): Traceback (most recent call last):
  File "/opt/ros/noetic/lib/python3/dist-packages/rospy/impl/tcpros_base.py", line 562, in connect
    self.read_header()
  File "/opt/ros/noetic/lib/python3/dist-packages/rospy/impl/tcpros_base.py", line 657, in read_header
    self._validate_header(read_ros_handshake_header(sock, self.read_buff, self.protocol.buff_size))
  File "/opt/ros/noetic/lib/python3/dist-packages/rospy/impl/tcpros_base.py", line 600, in _validate_header
    raise TransportInitError("remote error reported: %s"%header['error'])
rospy.exceptions.TransportInitError: remote error reported: received a connection for a nonexistent topic [/scan] from [TCPROS connection on port 50197 to [192.168.0.191:43144 on socket 111]] [/train_4892_1606205011396].

[rospy.internal][ERROR] 2020-11-24 08:04:02,094: Unable to initiate TCP/IP socket to 192.168.0.201:50197 (http://192.168.0.201:37341/): Traceback (most recent call last):
  File "/opt/ros/noetic/lib/python3/dist-packages/rospy/impl/tcpros_base.py", line 562, in connect
    self.read_header()
  File "/opt/ros/noetic/lib/python3/dist-packages/rospy/impl/tcpros_base.py", line 657, in read_header
    self._validate_header(read_ros_handshake_header(sock, self.read_buff, self.protocol.buff_size))
  File "/opt/ros/noetic/lib/python3/dist-packages/rospy/impl/tcpros_base.py", line 600, in _validate_header
    raise TransportInitError("remote error reported: %s"%header['error'])
rospy.exceptions.TransportInitError: remote error reported: received a connection for a nonexistent topic [/odom] from [TCPROS connection on port 50197 to [192.168.0.191:43146 on socket 111]] [/train_4892_1606205011396].

[rospy.internal][ERROR] 2020-11-24 08:04:09,950: Unable to initiate TCP/IP socket to 192.168.0.201:50197 (http://192.168.0.201:37341/): Traceback (most recent call last):
  File "/opt/ros/noetic/lib/python3/dist-packages/rospy/impl/tcpros_base.py", line 562, in connect
    self.read_header()
  File "/opt/ros/noetic/lib/python3/dist-packages/rospy/impl/tcpros_base.py", line 657, in read_header
    self._validate_header(read_ros_handshake_header(sock, self.read_buff, self.protocol.buff_size))
  File "/opt/ros/noetic/lib/python3/dist-packages/rospy/impl/tcpros_base.py", line 600, in _validate_header
    raise TransportInitError("remote error reported: %s"%header['error'])
rospy.exceptions.TransportInitError: remote error reported: received a connection for a nonexistent topic [/scan] from [TCPROS connection on port 50197 to [192.168.0.191:43148 on socket 111]] [/train_4892_1606205011396].

[rospy.internal][ERROR] 2020-11-24 08:04:10,102: Unable to initiate TCP/IP socket to 192.168.0.201:50197 (http://192.168.0.201:37341/): Traceback (most recent call last):
  File "/opt/ros/noetic/lib/python3/dist-packages/rospy/impl/tcpros_base.py", line 562, in connect
    self.read_header()
  File "/opt/ros/noetic/lib/python3/dist-packages/rospy/impl/tcpros_base.py", line 657, in read_header
    self._validate_header(read_ros_handshake_header(sock, self.read_buff, self.protocol.buff_size))
  File "/opt/ros/noetic/lib/python3/dist-packages/rospy/impl/tcpros_base.py", line 600, in _validate_header
    raise TransportInitError("remote error reported: %s"%header['error'])
rospy.exceptions.TransportInitError: remote error reported: received a connection for a nonexistent topic [/odom] from [TCPROS connection on port 50197 to [192.168.0.191:43150 on socket 111]] [/train_4892_1606205011396].

[rospy.internal][INFO] 2020-11-24 08:04:18,275: topic[/cmd_vel] adding connection to [/gazebo], count 1
[rospy.internal][INFO] 2020-11-24 08:04:21,774: topic[/cmd_vel] removing connection to /gazebo
[rospy.core][INFO] 2020-11-24 08:04:25,280: signal_shutdown [signal-2]
[rospy.internal][INFO] 2020-11-24 08:04:25,285: topic[/rosout] removing connection to /rosout
[rospy.internal][INFO] 2020-11-24 08:04:25,285: topic[/cmd_vel] removing connection to /bev_flow_estimator
[rospy.internal][INFO] 2020-11-24 08:04:25,286: topic[/is_finish_episode] removing connection to /episode_manager
[rospy.internal][INFO] 2020-11-24 08:04:25,286: topic[/bev/flow_image] removing connection to http://192.168.0.201:46143/
[rospy.internal][INFO] 2020-11-24 08:04:25,287: topic[/bev/occupancy_image] removing connection to http://192.168.0.201:46143/
[rospy.internal][INFO] 2020-11-24 08:04:25,287: topic[/odom] removing connection to http://192.168.0.201:37341/
[rospy.internal][WARNING] 2020-11-24 08:04:25,287: Unknown error initiating TCP/IP socket to 192.168.0.201:40321 (http://192.168.0.201:46143/): Traceback (most recent call last):
  File "/opt/ros/noetic/lib/python3/dist-packages/rospy/impl/tcpros_base.py", line 562, in connect
    self.read_header()
  File "/opt/ros/noetic/lib/python3/dist-packages/rospy/impl/tcpros_base.py", line 657, in read_header
    self._validate_header(read_ros_handshake_header(sock, self.read_buff, self.protocol.buff_size))
AttributeError: 'NoneType' object has no attribute 'buff_size'

[rospy.internal][INFO] 2020-11-24 08:04:25,288: topic[/start_goal_points] removing connection to http://192.168.0.201:41539/
[rospy.internal][INFO] 2020-11-24 08:04:25,288: topic[/scan] removing connection to http://192.168.0.201:37341/
[rospy.internal][WARNING] 2020-11-24 08:04:25,289: Unknown error initiating TCP/IP socket to 192.168.0.201:59627 (http://192.168.0.201:41539/): Traceback (most recent call last):
  File "/opt/ros/noetic/lib/python3/dist-packages/rospy/impl/tcpros_base.py", line 562, in connect
    self.read_header()
  File "/opt/ros/noetic/lib/python3/dist-packages/rospy/impl/tcpros_base.py", line 657, in read_header
    self._validate_header(read_ros_handshake_header(sock, self.read_buff, self.protocol.buff_size))
AttributeError: 'NoneType' object has no attribute 'buff_size'

[rospy.internal][INFO] 2020-11-24 08:04:25,289: topic[/scan] removing connection to http://192.168.0.201:36253/
[rospy.impl.masterslave][INFO] 2020-11-24 08:04:25,290: signal-2
[rospy.internal][WARNING] 2020-11-24 08:04:25,290: Unknown error initiating TCP/IP socket to 192.168.0.201:37763 (http://192.168.0.201:36253/): Traceback (most recent call last):
  File "/opt/ros/noetic/lib/python3/dist-packages/rospy/impl/tcpros_base.py", line 562, in connect
    self.read_header()
  File "/opt/ros/noetic/lib/python3/dist-packages/rospy/impl/tcpros_base.py", line 657, in read_header
    self._validate_header(read_ros_handshake_header(sock, self.read_buff, self.protocol.buff_size))
AttributeError: 'NoneType' object has no attribute 'buff_size'

[rospy.core][INFO] 2020-11-24 08:04:25,779: signal_shutdown [signal-2]
[rospy.core][INFO] 2020-11-24 08:04:25,821: signal_shutdown [signal-2]
[rospy.core][INFO] 2020-11-24 08:04:25,841: signal_shutdown [signal-2]
[rospy.core][INFO] 2020-11-24 08:04:25,871: signal_shutdown [signal-2]
[rospy.core][INFO] 2020-11-24 08:04:25,910: signal_shutdown [signal-2]
[rospy.core][INFO] 2020-11-24 08:04:25,946: signal_shutdown [signal-2]
[rospy.core][INFO] 2020-11-24 08:04:25,951: signal_shutdown [atexit]
