[rospy.client][INFO] 2020-11-24 08:23:28,226: init_node, name[/train_5459_1606206208198], pid[5459]
[xmlrpc][INFO] 2020-11-24 08:23:28,226: XML-RPC server binding to 0.0.0.0:0
[xmlrpc][INFO] 2020-11-24 08:23:28,227: Started XML-RPC server [http://192.168.0.191:36595/]
[rospy.init][INFO] 2020-11-24 08:23:28,227: ROS Slave URI: [http://192.168.0.191:36595/]
[rospy.impl.masterslave][INFO] 2020-11-24 08:23:28,228: _ready: http://192.168.0.191:36595/
[rospy.registration][INFO] 2020-11-24 08:23:28,229: Registering with master node http://192.168.0.201:11311
[xmlrpc][INFO] 2020-11-24 08:23:28,229: xml rpc node: starting XML-RPC server
[rospy.init][INFO] 2020-11-24 08:23:28,328: registered with master
[rospy.rosout][INFO] 2020-11-24 08:23:28,328: initializing /rosout core topic
[rospy.rosout][INFO] 2020-11-24 08:23:28,332: connected to core topic /rosout
[rospy.simtime][INFO] 2020-11-24 08:23:28,334: /use_sim_time is not set, will not subscribe to simulated time [/clock] topic
[rospy.internal][INFO] 2020-11-24 08:23:28,357: topic[/bev/flow_image] adding connection to [http://192.168.0.201:45107/], count 0
[rospy.internal][INFO] 2020-11-24 08:23:28,364: topic[/scan] adding connection to [http://192.168.0.201:37103/], count 0
[rospy.internal][INFO] 2020-11-24 08:23:28,367: topic[/scan] adding connection to [http://192.168.0.201:37341/], count 1
[rospy.internal][INFO] 2020-11-24 08:23:28,370: topic[/odom] adding connection to [http://192.168.0.201:37341/], count 0
[rospy.internal][INFO] 2020-11-24 08:23:28,371: topic[/start_goal_points] adding connection to [http://192.168.0.201:41539/], count 0
[rospy.internal][INFO] 2020-11-24 08:23:28,374: topic[/bev/occupancy_image] adding connection to [http://192.168.0.201:45107/], count 0
[rospy.internal][INFO] 2020-11-24 08:23:28,554: topic[/rosout] adding connection to [/rosout], count 0
[rospy.internal][INFO] 2020-11-24 08:23:28,555: topic[/is_finish_episode] adding connection to [/episode_manager], count 0
[rospy.internal][INFO] 2020-11-24 08:23:28,572: topic[/cmd_vel] adding connection to [/gazebo], count 0
[rospy.internal][INFO] 2020-11-24 08:23:28,576: topic[/cmd_vel] adding connection to [/bev_flow_estimator], count 1
[rospy.internal][ERROR] 2020-11-24 08:23:48,615: Unable to initiate TCP/IP socket to 192.168.0.201:50197 (http://192.168.0.201:37341/): Traceback (most recent call last):
  File "/opt/ros/noetic/lib/python3/dist-packages/rospy/impl/tcpros_base.py", line 562, in connect
    self.read_header()
  File "/opt/ros/noetic/lib/python3/dist-packages/rospy/impl/tcpros_base.py", line 657, in read_header
    self._validate_header(read_ros_handshake_header(sock, self.read_buff, self.protocol.buff_size))
  File "/opt/ros/noetic/lib/python3/dist-packages/rospy/impl/tcpros_base.py", line 600, in _validate_header
    raise TransportInitError("remote error reported: %s"%header['error'])
rospy.exceptions.TransportInitError: remote error reported: received a connection for a nonexistent topic [/scan] from [TCPROS connection on port 50197 to [192.168.0.191:43670 on socket 152]] [/train_5459_1606206208198].

[rospy.internal][ERROR] 2020-11-24 08:23:48,747: Unable to initiate TCP/IP socket to 192.168.0.201:50197 (http://192.168.0.201:37341/): Traceback (most recent call last):
  File "/opt/ros/noetic/lib/python3/dist-packages/rospy/impl/tcpros_base.py", line 562, in connect
    self.read_header()
  File "/opt/ros/noetic/lib/python3/dist-packages/rospy/impl/tcpros_base.py", line 657, in read_header
    self._validate_header(read_ros_handshake_header(sock, self.read_buff, self.protocol.buff_size))
  File "/opt/ros/noetic/lib/python3/dist-packages/rospy/impl/tcpros_base.py", line 600, in _validate_header
    raise TransportInitError("remote error reported: %s"%header['error'])
rospy.exceptions.TransportInitError: remote error reported: received a connection for a nonexistent topic [/odom] from [TCPROS connection on port 50197 to [192.168.0.191:43672 on socket 125]] [/train_5459_1606206208198].

[rospy.internal][INFO] 2020-11-24 08:23:49,140: topic[/cmd_vel] removing connection to /gazebo
[rospy.internal][ERROR] 2020-11-24 08:23:49,617: Unable to initiate TCP/IP socket to 192.168.0.201:50197 (http://192.168.0.201:37341/): Traceback (most recent call last):
  File "/opt/ros/noetic/lib/python3/dist-packages/rospy/impl/tcpros_base.py", line 562, in connect
    self.read_header()
  File "/opt/ros/noetic/lib/python3/dist-packages/rospy/impl/tcpros_base.py", line 657, in read_header
    self._validate_header(read_ros_handshake_header(sock, self.read_buff, self.protocol.buff_size))
  File "/opt/ros/noetic/lib/python3/dist-packages/rospy/impl/tcpros_base.py", line 600, in _validate_header
    raise TransportInitError("remote error reported: %s"%header['error'])
rospy.exceptions.TransportInitError: remote error reported: received a connection for a nonexistent topic [/scan] from [TCPROS connection on port 50197 to [192.168.0.191:43674 on socket 125]] [/train_5459_1606206208198].

[rospy.internal][ERROR] 2020-11-24 08:23:49,750: Unable to initiate TCP/IP socket to 192.168.0.201:50197 (http://192.168.0.201:37341/): Traceback (most recent call last):
  File "/opt/ros/noetic/lib/python3/dist-packages/rospy/impl/tcpros_base.py", line 562, in connect
    self.read_header()
  File "/opt/ros/noetic/lib/python3/dist-packages/rospy/impl/tcpros_base.py", line 657, in read_header
    self._validate_header(read_ros_handshake_header(sock, self.read_buff, self.protocol.buff_size))
  File "/opt/ros/noetic/lib/python3/dist-packages/rospy/impl/tcpros_base.py", line 600, in _validate_header
    raise TransportInitError("remote error reported: %s"%header['error'])
rospy.exceptions.TransportInitError: remote error reported: received a connection for a nonexistent topic [/odom] from [TCPROS connection on port 50197 to [192.168.0.191:43676 on socket 125]] [/train_5459_1606206208198].

[rospy.internal][ERROR] 2020-11-24 08:23:51,621: Unable to initiate TCP/IP socket to 192.168.0.201:50197 (http://192.168.0.201:37341/): Traceback (most recent call last):
  File "/opt/ros/noetic/lib/python3/dist-packages/rospy/impl/tcpros_base.py", line 562, in connect
    self.read_header()
  File "/opt/ros/noetic/lib/python3/dist-packages/rospy/impl/tcpros_base.py", line 657, in read_header
    self._validate_header(read_ros_handshake_header(sock, self.read_buff, self.protocol.buff_size))
  File "/opt/ros/noetic/lib/python3/dist-packages/rospy/impl/tcpros_base.py", line 600, in _validate_header
    raise TransportInitError("remote error reported: %s"%header['error'])
rospy.exceptions.TransportInitError: remote error reported: received a connection for a nonexistent topic [/scan] from [TCPROS connection on port 50197 to [192.168.0.191:43678 on socket 125]] [/train_5459_1606206208198].

[rospy.internal][ERROR] 2020-11-24 08:23:51,753: Unable to initiate TCP/IP socket to 192.168.0.201:50197 (http://192.168.0.201:37341/): Traceback (most recent call last):
  File "/opt/ros/noetic/lib/python3/dist-packages/rospy/impl/tcpros_base.py", line 562, in connect
    self.read_header()
  File "/opt/ros/noetic/lib/python3/dist-packages/rospy/impl/tcpros_base.py", line 657, in read_header
    self._validate_header(read_ros_handshake_header(sock, self.read_buff, self.protocol.buff_size))
  File "/opt/ros/noetic/lib/python3/dist-packages/rospy/impl/tcpros_base.py", line 600, in _validate_header
    raise TransportInitError("remote error reported: %s"%header['error'])
rospy.exceptions.TransportInitError: remote error reported: received a connection for a nonexistent topic [/odom] from [TCPROS connection on port 50197 to [192.168.0.191:43680 on socket 125]] [/train_5459_1606206208198].

[rospy.internal][ERROR] 2020-11-24 08:23:55,626: Unable to initiate TCP/IP socket to 192.168.0.201:50197 (http://192.168.0.201:37341/): Traceback (most recent call last):
  File "/opt/ros/noetic/lib/python3/dist-packages/rospy/impl/tcpros_base.py", line 562, in connect
    self.read_header()
  File "/opt/ros/noetic/lib/python3/dist-packages/rospy/impl/tcpros_base.py", line 657, in read_header
    self._validate_header(read_ros_handshake_header(sock, self.read_buff, self.protocol.buff_size))
  File "/opt/ros/noetic/lib/python3/dist-packages/rospy/impl/tcpros_base.py", line 600, in _validate_header
    raise TransportInitError("remote error reported: %s"%header['error'])
rospy.exceptions.TransportInitError: remote error reported: received a connection for a nonexistent topic [/scan] from [TCPROS connection on port 50197 to [192.168.0.191:43682 on socket 91]] [/train_5459_1606206208198].

[rospy.internal][ERROR] 2020-11-24 08:23:55,759: Unable to initiate TCP/IP socket to 192.168.0.201:50197 (http://192.168.0.201:37341/): Traceback (most recent call last):
  File "/opt/ros/noetic/lib/python3/dist-packages/rospy/impl/tcpros_base.py", line 562, in connect
    self.read_header()
  File "/opt/ros/noetic/lib/python3/dist-packages/rospy/impl/tcpros_base.py", line 657, in read_header
    self._validate_header(read_ros_handshake_header(sock, self.read_buff, self.protocol.buff_size))
  File "/opt/ros/noetic/lib/python3/dist-packages/rospy/impl/tcpros_base.py", line 600, in _validate_header
    raise TransportInitError("remote error reported: %s"%header['error'])
rospy.exceptions.TransportInitError: remote error reported: received a connection for a nonexistent topic [/odom] from [TCPROS connection on port 50197 to [192.168.0.191:43684 on socket 91]] [/train_5459_1606206208198].

[rospy.internal][ERROR] 2020-11-24 08:24:03,768: Unable to initiate TCP/IP socket to 192.168.0.201:50197 (http://192.168.0.201:37341/): Traceback (most recent call last):
  File "/opt/ros/noetic/lib/python3/dist-packages/rospy/impl/tcpros_base.py", line 562, in connect
    self.read_header()
  File "/opt/ros/noetic/lib/python3/dist-packages/rospy/impl/tcpros_base.py", line 657, in read_header
    self._validate_header(read_ros_handshake_header(sock, self.read_buff, self.protocol.buff_size))
  File "/opt/ros/noetic/lib/python3/dist-packages/rospy/impl/tcpros_base.py", line 600, in _validate_header
    raise TransportInitError("remote error reported: %s"%header['error'])
rospy.exceptions.TransportInitError: remote error reported: received a connection for a nonexistent topic [/odom] from [TCPROS connection on port 50197 to [192.168.0.191:43688 on socket 148]] [/train_5459_1606206208198].

[rospy.internal][ERROR] 2020-11-24 08:24:19,786: Unable to initiate TCP/IP socket to 192.168.0.201:50197 (http://192.168.0.201:37341/): Traceback (most recent call last):
  File "/opt/ros/noetic/lib/python3/dist-packages/rospy/impl/tcpros_base.py", line 562, in connect
    self.read_header()
  File "/opt/ros/noetic/lib/python3/dist-packages/rospy/impl/tcpros_base.py", line 657, in read_header
    self._validate_header(read_ros_handshake_header(sock, self.read_buff, self.protocol.buff_size))
  File "/opt/ros/noetic/lib/python3/dist-packages/rospy/impl/tcpros_base.py", line 600, in _validate_header
    raise TransportInitError("remote error reported: %s"%header['error'])
rospy.exceptions.TransportInitError: remote error reported: received a connection for a nonexistent topic [/odom] from [TCPROS connection on port 50197 to [192.168.0.191:43690 on socket 125]] [/train_5459_1606206208198].

[rospy.internal][ERROR] 2020-11-24 08:24:51,821: Unable to initiate TCP/IP socket to 192.168.0.201:50197 (http://192.168.0.201:37341/): Traceback (most recent call last):
  File "/opt/ros/noetic/lib/python3/dist-packages/rospy/impl/tcpros_base.py", line 562, in connect
    self.read_header()
  File "/opt/ros/noetic/lib/python3/dist-packages/rospy/impl/tcpros_base.py", line 657, in read_header
    self._validate_header(read_ros_handshake_header(sock, self.read_buff, self.protocol.buff_size))
  File "/opt/ros/noetic/lib/python3/dist-packages/rospy/impl/tcpros_base.py", line 600, in _validate_header
    raise TransportInitError("remote error reported: %s"%header['error'])
rospy.exceptions.TransportInitError: remote error reported: received a connection for a nonexistent topic [/odom] from [TCPROS connection on port 50197 to [192.168.0.191:43692 on socket 125]] [/train_5459_1606206208198].

[rospy.core][INFO] 2020-11-24 08:24:57,278: signal_shutdown [signal-2]
[rospy.internal][INFO] 2020-11-24 08:24:57,285: topic[/rosout] removing connection to /rosout
[rospy.internal][INFO] 2020-11-24 08:24:57,286: topic[/cmd_vel] removing connection to /bev_flow_estimator
[rospy.internal][INFO] 2020-11-24 08:24:57,287: topic[/is_finish_episode] removing connection to /episode_manager
[rospy.internal][INFO] 2020-11-24 08:24:57,287: topic[/bev/flow_image] removing connection to http://192.168.0.201:45107/
[rospy.internal][INFO] 2020-11-24 08:24:57,288: topic[/bev/occupancy_image] removing connection to http://192.168.0.201:45107/
[rospy.internal][INFO] 2020-11-24 08:24:57,288: topic[/odom] removing connection to http://192.168.0.201:37341/
[rospy.internal][WARNING] 2020-11-24 08:24:57,289: Unknown error initiating TCP/IP socket to 192.168.0.201:55471 (http://192.168.0.201:45107/): Traceback (most recent call last):
  File "/opt/ros/noetic/lib/python3/dist-packages/rospy/impl/tcpros_base.py", line 562, in connect
    self.read_header()
  File "/opt/ros/noetic/lib/python3/dist-packages/rospy/impl/tcpros_base.py", line 657, in read_header
    self._validate_header(read_ros_handshake_header(sock, self.read_buff, self.protocol.buff_size))
AttributeError: 'NoneType' object has no attribute 'buff_size'

[rospy.internal][INFO] 2020-11-24 08:24:57,289: topic[/start_goal_points] removing connection to http://192.168.0.201:41539/
[rospy.internal][INFO] 2020-11-24 08:24:57,289: topic[/scan] removing connection to http://192.168.0.201:37103/
[rospy.internal][INFO] 2020-11-24 08:24:57,290: topic[/scan] removing connection to http://192.168.0.201:37341/
[rospy.impl.masterslave][INFO] 2020-11-24 08:24:57,291: signal-2
[rospy.internal][WARNING] 2020-11-24 08:24:57,291: Unknown error initiating TCP/IP socket to 192.168.0.201:59627 (http://192.168.0.201:41539/): Traceback (most recent call last):
  File "/opt/ros/noetic/lib/python3/dist-packages/rospy/impl/tcpros_base.py", line 562, in connect
    self.read_header()
  File "/opt/ros/noetic/lib/python3/dist-packages/rospy/impl/tcpros_base.py", line 657, in read_header
    self._validate_header(read_ros_handshake_header(sock, self.read_buff, self.protocol.buff_size))
AttributeError: 'NoneType' object has no attribute 'buff_size'

[rospy.core][INFO] 2020-11-24 08:24:57,778: signal_shutdown [signal-2]
[rospy.core][INFO] 2020-11-24 08:24:57,815: signal_shutdown [signal-2]
[rospy.core][INFO] 2020-11-24 08:24:57,837: signal_shutdown [signal-2]
[rospy.core][INFO] 2020-11-24 08:24:57,870: signal_shutdown [signal-2]
[rospy.core][INFO] 2020-11-24 08:24:57,920: signal_shutdown [signal-2]
[rospy.core][INFO] 2020-11-24 08:24:57,953: signal_shutdown [signal-2]
[rospy.core][INFO] 2020-11-24 08:24:57,965: signal_shutdown [signal-2]
[rospy.core][INFO] 2020-11-24 08:24:57,969: signal_shutdown [atexit]
