[rospy.client][INFO] 2020-11-20 12:51:33,416: init_node, name[/train_2647_1605876693385], pid[2647]
[xmlrpc][INFO] 2020-11-20 12:51:33,417: XML-RPC server binding to 0.0.0.0:0
[xmlrpc][INFO] 2020-11-20 12:51:33,417: Started XML-RPC server [http://192.168.0.191:46423/]
[rospy.init][INFO] 2020-11-20 12:51:33,418: ROS Slave URI: [http://192.168.0.191:46423/]
[rospy.impl.masterslave][INFO] 2020-11-20 12:51:33,418: _ready: http://192.168.0.191:46423/
[rospy.registration][INFO] 2020-11-20 12:51:33,419: Registering with master node http://192.168.0.201:11311
[xmlrpc][INFO] 2020-11-20 12:51:33,420: xml rpc node: starting XML-RPC server
[rospy.init][INFO] 2020-11-20 12:51:33,518: registered with master
[rospy.rosout][INFO] 2020-11-20 12:51:33,519: initializing /rosout core topic
[rospy.rosout][INFO] 2020-11-20 12:51:33,525: connected to core topic /rosout
[rospy.simtime][INFO] 2020-11-20 12:51:33,526: /use_sim_time is not set, will not subscribe to simulated time [/clock] topic
[rospy.internal][INFO] 2020-11-20 12:51:33,538: topic[/bev/flow_image] adding connection to [http://192.168.0.201:37547/], count 0
[rospy.internal][INFO] 2020-11-20 12:51:33,541: topic[/bev/occupancy_image] adding connection to [http://192.168.0.201:37547/], count 0
[rospy.internal][INFO] 2020-11-20 12:51:33,545: topic[/odom] adding connection to [http://192.168.0.201:36467/], count 0
[rospy.internal][INFO] 2020-11-20 12:51:33,550: topic[/start_goal_points] adding connection to [http://192.168.0.201:44137/], count 0
[rospy.internal][INFO] 2020-11-20 12:51:33,556: topic[/scan] adding connection to [http://192.168.0.201:36467/], count 0
[rospy.internal][INFO] 2020-11-20 12:51:33,557: topic[/scan] adding connection to [http://192.168.0.201:41431/], count 1
[rospy.internal][INFO] 2020-11-20 12:51:33,689: topic[/cmd_vel] adding connection to [/gazebo], count 0
[rospy.internal][INFO] 2020-11-20 12:51:33,690: topic[/cmd_vel] adding connection to [/bev_flow_estimator], count 1
[rosout][ERROR] 2020-11-20 12:51:33,718: bad callback: <bound method ROSNode.laser_callback of <__main__.ROSNode object at 0x7efc7f1881f0>>
Traceback (most recent call last):
  File "/opt/ros/noetic/lib/python3/dist-packages/rospy/topics.py", line 750, in _invoke_callback
    cb(msg)
  File "./train.py", line 152, in laser_callback
    print("ROS:scan_data[",i,"] =" ,self.scan_data[i])
IndexError: index 39 is out of bounds for axis 0 with size 5

[rosout][ERROR] 2020-11-20 12:51:33,747: bad callback: <bound method ROSNode.laser_callback of <__main__.ROSNode object at 0x7efc7f1881f0>>
Traceback (most recent call last):
  File "/opt/ros/noetic/lib/python3/dist-packages/rospy/topics.py", line 750, in _invoke_callback
    cb(msg)
  File "./train.py", line 152, in laser_callback
    print("ROS:scan_data[",i,"] =" ,self.scan_data[i])
IndexError: index 221 is out of bounds for axis 0 with size 6

[rospy.internal][INFO] 2020-11-20 12:51:33,788: topic[/rosout] adding connection to [/rosout], count 0
[rospy.internal][INFO] 2020-11-20 12:51:33,790: topic[/is_created_scenarios] adding connection to [/episode_manager], count 0
[rosout][ERROR] 2020-11-20 12:51:33,952: bad callback: <bound method ROSNode.laser_callback of <__main__.ROSNode object at 0x7efc7f1881f0>>
Traceback (most recent call last):
  File "/opt/ros/noetic/lib/python3/dist-packages/rospy/topics.py", line 750, in _invoke_callback
    cb(msg)
  File "./train.py", line 152, in laser_callback
    print("ROS:scan_data[",i,"] =" ,self.scan_data[i])
IndexError: index 39 is out of bounds for axis 0 with size 10

[rosout][ERROR] 2020-11-20 12:51:33,983: bad callback: <bound method ROSNode.laser_callback of <__main__.ROSNode object at 0x7efc7f1881f0>>
Traceback (most recent call last):
  File "/opt/ros/noetic/lib/python3/dist-packages/rospy/topics.py", line 750, in _invoke_callback
    cb(msg)
  File "./train.py", line 152, in laser_callback
    print("ROS:scan_data[",i,"] =" ,self.scan_data[i])
IndexError: index 221 is out of bounds for axis 0 with size 11

[rosout][ERROR] 2020-11-20 12:51:34,198: bad callback: <bound method ROSNode.laser_callback of <__main__.ROSNode object at 0x7efc7f1881f0>>
Traceback (most recent call last):
  File "/opt/ros/noetic/lib/python3/dist-packages/rospy/topics.py", line 750, in _invoke_callback
    cb(msg)
  File "./train.py", line 152, in laser_callback
    print("ROS:scan_data[",i,"] =" ,self.scan_data[i])
IndexError: index 39 is out of bounds for axis 0 with size 15

[rosout][ERROR] 2020-11-20 12:51:34,233: bad callback: <bound method ROSNode.laser_callback of <__main__.ROSNode object at 0x7efc7f1881f0>>
Traceback (most recent call last):
  File "/opt/ros/noetic/lib/python3/dist-packages/rospy/topics.py", line 750, in _invoke_callback
    cb(msg)
  File "./train.py", line 152, in laser_callback
    print("ROS:scan_data[",i,"] =" ,self.scan_data[i])
IndexError: index 221 is out of bounds for axis 0 with size 16

[rosout][ERROR] 2020-11-20 12:51:34,438: bad callback: <bound method ROSNode.laser_callback of <__main__.ROSNode object at 0x7efc7f1881f0>>
Traceback (most recent call last):
  File "/opt/ros/noetic/lib/python3/dist-packages/rospy/topics.py", line 750, in _invoke_callback
    cb(msg)
  File "./train.py", line 152, in laser_callback
    print("ROS:scan_data[",i,"] =" ,self.scan_data[i])
IndexError: index 39 is out of bounds for axis 0 with size 20

[rosout][ERROR] 2020-11-20 12:51:34,472: bad callback: <bound method ROSNode.laser_callback of <__main__.ROSNode object at 0x7efc7f1881f0>>
Traceback (most recent call last):
  File "/opt/ros/noetic/lib/python3/dist-packages/rospy/topics.py", line 750, in _invoke_callback
    cb(msg)
  File "./train.py", line 152, in laser_callback
    print("ROS:scan_data[",i,"] =" ,self.scan_data[i])
IndexError: index 225 is out of bounds for axis 0 with size 21

[rosout][ERROR] 2020-11-20 12:51:34,678: bad callback: <bound method ROSNode.laser_callback of <__main__.ROSNode object at 0x7efc7f1881f0>>
Traceback (most recent call last):
  File "/opt/ros/noetic/lib/python3/dist-packages/rospy/topics.py", line 750, in _invoke_callback
    cb(msg)
  File "./train.py", line 152, in laser_callback
    print("ROS:scan_data[",i,"] =" ,self.scan_data[i])
IndexError: index 39 is out of bounds for axis 0 with size 25

[rosout][ERROR] 2020-11-20 12:51:34,716: bad callback: <bound method ROSNode.laser_callback of <__main__.ROSNode object at 0x7efc7f1881f0>>
Traceback (most recent call last):
  File "/opt/ros/noetic/lib/python3/dist-packages/rospy/topics.py", line 750, in _invoke_callback
    cb(msg)
  File "./train.py", line 152, in laser_callback
    print("ROS:scan_data[",i,"] =" ,self.scan_data[i])
IndexError: index 221 is out of bounds for axis 0 with size 26

[rosout][ERROR] 2020-11-20 12:51:34,916: bad callback: <bound method ROSNode.laser_callback of <__main__.ROSNode object at 0x7efc7f1881f0>>
Traceback (most recent call last):
  File "/opt/ros/noetic/lib/python3/dist-packages/rospy/topics.py", line 750, in _invoke_callback
    cb(msg)
  File "./train.py", line 152, in laser_callback
    print("ROS:scan_data[",i,"] =" ,self.scan_data[i])
IndexError: index 39 is out of bounds for axis 0 with size 30

[rosout][ERROR] 2020-11-20 12:51:34,951: bad callback: <bound method ROSNode.laser_callback of <__main__.ROSNode object at 0x7efc7f1881f0>>
Traceback (most recent call last):
  File "/opt/ros/noetic/lib/python3/dist-packages/rospy/topics.py", line 750, in _invoke_callback
    cb(msg)
  File "./train.py", line 152, in laser_callback
    print("ROS:scan_data[",i,"] =" ,self.scan_data[i])
IndexError: index 221 is out of bounds for axis 0 with size 31

[rosout][ERROR] 2020-11-20 12:51:35,159: bad callback: <bound method ROSNode.laser_callback of <__main__.ROSNode object at 0x7efc7f1881f0>>
Traceback (most recent call last):
  File "/opt/ros/noetic/lib/python3/dist-packages/rospy/topics.py", line 750, in _invoke_callback
    cb(msg)
  File "./train.py", line 152, in laser_callback
    print("ROS:scan_data[",i,"] =" ,self.scan_data[i])
IndexError: index 39 is out of bounds for axis 0 with size 35

[rosout][ERROR] 2020-11-20 12:51:35,195: bad callback: <bound method ROSNode.laser_callback of <__main__.ROSNode object at 0x7efc7f1881f0>>
Traceback (most recent call last):
  File "/opt/ros/noetic/lib/python3/dist-packages/rospy/topics.py", line 750, in _invoke_callback
    cb(msg)
  File "./train.py", line 152, in laser_callback
    print("ROS:scan_data[",i,"] =" ,self.scan_data[i])
IndexError: index 221 is out of bounds for axis 0 with size 36

[rosout][ERROR] 2020-11-20 12:51:35,406: bad callback: <bound method ROSNode.laser_callback of <__main__.ROSNode object at 0x7efc7f1881f0>>
Traceback (most recent call last):
  File "/opt/ros/noetic/lib/python3/dist-packages/rospy/topics.py", line 750, in _invoke_callback
    cb(msg)
  File "./train.py", line 152, in laser_callback
    print("ROS:scan_data[",i,"] =" ,self.scan_data[i])
IndexError: index 357 is out of bounds for axis 0 with size 294

[rosout][ERROR] 2020-11-20 12:51:35,433: bad callback: <bound method ROSNode.laser_callback of <__main__.ROSNode object at 0x7efc7f1881f0>>
Traceback (most recent call last):
  File "/opt/ros/noetic/lib/python3/dist-packages/rospy/topics.py", line 750, in _invoke_callback
    cb(msg)
  File "./train.py", line 152, in laser_callback
    print("ROS:scan_data[",i,"] =" ,self.scan_data[i])
IndexError: index 319 is out of bounds for axis 0 with size 319

[rospy.core][INFO] 2020-11-20 12:51:36,095: signal_shutdown [atexit]
[rospy.internal][INFO] 2020-11-20 12:51:36,099: topic[/rosout] removing connection to /rosout
[rospy.internal][INFO] 2020-11-20 12:51:36,099: topic[/cmd_vel] removing connection to /gazebo
[rospy.internal][INFO] 2020-11-20 12:51:36,099: topic[/cmd_vel] removing connection to /bev_flow_estimator
[rospy.internal][INFO] 2020-11-20 12:51:36,099: topic[/is_created_scenarios] removing connection to /episode_manager
[rospy.internal][INFO] 2020-11-20 12:51:36,100: topic[/bev/flow_image] removing connection to http://192.168.0.201:37547/
[rospy.internal][INFO] 2020-11-20 12:51:36,100: topic[/bev/occupancy_image] removing connection to http://192.168.0.201:37547/
[rospy.internal][INFO] 2020-11-20 12:51:36,100: topic[/odom] removing connection to http://192.168.0.201:36467/
[rospy.internal][INFO] 2020-11-20 12:51:36,101: topic[/start_goal_points] removing connection to http://192.168.0.201:44137/
[rospy.internal][INFO] 2020-11-20 12:51:36,101: topic[/scan] removing connection to http://192.168.0.201:36467/
[rospy.internal][INFO] 2020-11-20 12:51:36,102: topic[/scan] removing connection to http://192.168.0.201:41431/
[rospy.internal][WARNING] 2020-11-20 12:51:36,102: Unknown error initiating TCP/IP socket to 192.168.0.201:57757 (http://192.168.0.201:37547/): Traceback (most recent call last):
  File "/opt/ros/noetic/lib/python3/dist-packages/rospy/impl/tcpros_base.py", line 562, in connect
    self.read_header()
  File "/opt/ros/noetic/lib/python3/dist-packages/rospy/impl/tcpros_base.py", line 657, in read_header
    self._validate_header(read_ros_handshake_header(sock, self.read_buff, self.protocol.buff_size))
AttributeError: 'NoneType' object has no attribute 'buff_size'

[rospy.impl.masterslave][INFO] 2020-11-20 12:51:36,102: atexit
[rospy.internal][WARNING] 2020-11-20 12:51:36,103: Unknown error initiating TCP/IP socket to 192.168.0.201:57757 (http://192.168.0.201:37547/): Traceback (most recent call last):
  File "/opt/ros/noetic/lib/python3/dist-packages/rospy/impl/tcpros_base.py", line 562, in connect
    self.read_header()
  File "/opt/ros/noetic/lib/python3/dist-packages/rospy/impl/tcpros_base.py", line 657, in read_header
    self._validate_header(read_ros_handshake_header(sock, self.read_buff, self.protocol.buff_size))
AttributeError: 'NoneType' object has no attribute 'buff_size'

[rospy.internal][WARNING] 2020-11-20 12:51:36,104: Unknown error initiating TCP/IP socket to 192.168.0.201:47641 (http://192.168.0.201:44137/): Traceback (most recent call last):
  File "/opt/ros/noetic/lib/python3/dist-packages/rospy/impl/tcpros_base.py", line 562, in connect
    self.read_header()
  File "/opt/ros/noetic/lib/python3/dist-packages/rospy/impl/tcpros_base.py", line 657, in read_header
    self._validate_header(read_ros_handshake_header(sock, self.read_buff, self.protocol.buff_size))
AttributeError: 'NoneType' object has no attribute 'buff_size'

