[rospy.client][INFO] 2020-11-29 08:19:05,997: init_node, name[/train_394_1606637945965], pid[394]
[xmlrpc][INFO] 2020-11-29 08:19:05,997: XML-RPC server binding to 0.0.0.0:0
[xmlrpc][INFO] 2020-11-29 08:19:05,998: Started XML-RPC server [http://192.168.0.191:37887/]
[rospy.init][INFO] 2020-11-29 08:19:05,999: ROS Slave URI: [http://192.168.0.191:37887/]
[rospy.impl.masterslave][INFO] 2020-11-29 08:19:05,999: _ready: http://192.168.0.191:37887/
[rospy.registration][INFO] 2020-11-29 08:19:06,000: Registering with master node http://192.168.0.201:11311
[xmlrpc][INFO] 2020-11-29 08:19:06,000: xml rpc node: starting XML-RPC server
[rospy.init][INFO] 2020-11-29 08:19:06,099: registered with master
[rospy.rosout][INFO] 2020-11-29 08:19:06,100: initializing /rosout core topic
[rospy.rosout][INFO] 2020-11-29 08:19:06,107: connected to core topic /rosout
[rospy.simtime][INFO] 2020-11-29 08:19:06,109: /use_sim_time is not set, will not subscribe to simulated time [/clock] topic
[rospy.internal][INFO] 2020-11-29 08:19:06,410: topic[/rosout] adding connection to [/rosout], count 0
[rospy.internal][INFO] 2020-11-29 08:19:11,923: topic[/is_start_episode] adding connection to [http://192.168.0.201:35281/], count 0
[rospy.internal][INFO] 2020-11-29 08:19:11,923: topic[/start_goal_points] adding connection to [http://192.168.0.201:41767/], count 0
[rospy.internal][INFO] 2020-11-29 08:19:12,019: topic[/episode_watcher/is_finish_episode] adding connection to [/episode_manager], count 0
[rosout][ERROR] 2020-11-29 08:19:14,338: bad callback: <bound method ROSNode.pose_array_callback of <__main__.ROSNode object at 0x7f09d547e580>>
Traceback (most recent call last):
  File "/opt/ros/noetic/lib/python3/dist-packages/rospy/topics.py", line 750, in _invoke_callback
    cb(msg)
  File "./train.py", line 139, in pose_array_callback
    self.global_start = msg.poses[0]
IndexError: list index out of range

[rosout][ERROR] 2020-11-29 08:19:14,341: bad callback: <bound method ROSNode.pose_array_callback of <__main__.ROSNode object at 0x7f09d547e580>>
Traceback (most recent call last):
  File "/opt/ros/noetic/lib/python3/dist-packages/rospy/topics.py", line 750, in _invoke_callback
    cb(msg)
  File "./train.py", line 139, in pose_array_callback
    self.global_start = msg.poses[0]
IndexError: list index out of range

[rosout][ERROR] 2020-11-29 08:19:14,347: bad callback: <bound method ROSNode.pose_array_callback of <__main__.ROSNode object at 0x7f09d547e580>>
Traceback (most recent call last):
  File "/opt/ros/noetic/lib/python3/dist-packages/rospy/topics.py", line 750, in _invoke_callback
    cb(msg)
  File "./train.py", line 139, in pose_array_callback
    self.global_start = msg.poses[0]
IndexError: list index out of range

[rosout][ERROR] 2020-11-29 08:19:14,356: bad callback: <bound method ROSNode.pose_array_callback of <__main__.ROSNode object at 0x7f09d547e580>>
Traceback (most recent call last):
  File "/opt/ros/noetic/lib/python3/dist-packages/rospy/topics.py", line 750, in _invoke_callback
    cb(msg)
  File "./train.py", line 139, in pose_array_callback
    self.global_start = msg.poses[0]
IndexError: list index out of range

[rosout][ERROR] 2020-11-29 08:19:14,367: bad callback: <bound method ROSNode.pose_array_callback of <__main__.ROSNode object at 0x7f09d547e580>>
Traceback (most recent call last):
  File "/opt/ros/noetic/lib/python3/dist-packages/rospy/topics.py", line 750, in _invoke_callback
    cb(msg)
  File "./train.py", line 139, in pose_array_callback
    self.global_start = msg.poses[0]
IndexError: list index out of range

[rosout][ERROR] 2020-11-29 08:19:14,376: bad callback: <bound method ROSNode.pose_array_callback of <__main__.ROSNode object at 0x7f09d547e580>>
Traceback (most recent call last):
  File "/opt/ros/noetic/lib/python3/dist-packages/rospy/topics.py", line 750, in _invoke_callback
    cb(msg)
  File "./train.py", line 139, in pose_array_callback
    self.global_start = msg.poses[0]
IndexError: list index out of range

[rosout][ERROR] 2020-11-29 08:19:14,386: bad callback: <bound method ROSNode.pose_array_callback of <__main__.ROSNode object at 0x7f09d547e580>>
Traceback (most recent call last):
  File "/opt/ros/noetic/lib/python3/dist-packages/rospy/topics.py", line 750, in _invoke_callback
    cb(msg)
  File "./train.py", line 139, in pose_array_callback
    self.global_start = msg.poses[0]
IndexError: list index out of range

[rosout][ERROR] 2020-11-29 08:19:14,396: bad callback: <bound method ROSNode.pose_array_callback of <__main__.ROSNode object at 0x7f09d547e580>>
Traceback (most recent call last):
  File "/opt/ros/noetic/lib/python3/dist-packages/rospy/topics.py", line 750, in _invoke_callback
    cb(msg)
  File "./train.py", line 139, in pose_array_callback
    self.global_start = msg.poses[0]
IndexError: list index out of range

[rosout][ERROR] 2020-11-29 08:19:14,406: bad callback: <bound method ROSNode.pose_array_callback of <__main__.ROSNode object at 0x7f09d547e580>>
Traceback (most recent call last):
  File "/opt/ros/noetic/lib/python3/dist-packages/rospy/topics.py", line 750, in _invoke_callback
    cb(msg)
  File "./train.py", line 139, in pose_array_callback
    self.global_start = msg.poses[0]
IndexError: list index out of range

[rosout][ERROR] 2020-11-29 08:19:14,416: bad callback: <bound method ROSNode.pose_array_callback of <__main__.ROSNode object at 0x7f09d547e580>>
Traceback (most recent call last):
  File "/opt/ros/noetic/lib/python3/dist-packages/rospy/topics.py", line 750, in _invoke_callback
    cb(msg)
  File "./train.py", line 139, in pose_array_callback
    self.global_start = msg.poses[0]
IndexError: list index out of range

[rosout][ERROR] 2020-11-29 08:19:14,426: bad callback: <bound method ROSNode.pose_array_callback of <__main__.ROSNode object at 0x7f09d547e580>>
Traceback (most recent call last):
  File "/opt/ros/noetic/lib/python3/dist-packages/rospy/topics.py", line 750, in _invoke_callback
    cb(msg)
  File "./train.py", line 139, in pose_array_callback
    self.global_start = msg.poses[0]
IndexError: list index out of range

[rosout][ERROR] 2020-11-29 08:19:14,436: bad callback: <bound method ROSNode.pose_array_callback of <__main__.ROSNode object at 0x7f09d547e580>>
Traceback (most recent call last):
  File "/opt/ros/noetic/lib/python3/dist-packages/rospy/topics.py", line 750, in _invoke_callback
    cb(msg)
  File "./train.py", line 139, in pose_array_callback
    self.global_start = msg.poses[0]
IndexError: list index out of range

[rosout][ERROR] 2020-11-29 08:19:14,446: bad callback: <bound method ROSNode.pose_array_callback of <__main__.ROSNode object at 0x7f09d547e580>>
Traceback (most recent call last):
  File "/opt/ros/noetic/lib/python3/dist-packages/rospy/topics.py", line 750, in _invoke_callback
    cb(msg)
  File "./train.py", line 139, in pose_array_callback
    self.global_start = msg.poses[0]
IndexError: list index out of range

[rosout][ERROR] 2020-11-29 08:19:14,456: bad callback: <bound method ROSNode.pose_array_callback of <__main__.ROSNode object at 0x7f09d547e580>>
Traceback (most recent call last):
  File "/opt/ros/noetic/lib/python3/dist-packages/rospy/topics.py", line 750, in _invoke_callback
    cb(msg)
  File "./train.py", line 139, in pose_array_callback
    self.global_start = msg.poses[0]
IndexError: list index out of range

[rosout][ERROR] 2020-11-29 08:19:14,466: bad callback: <bound method ROSNode.pose_array_callback of <__main__.ROSNode object at 0x7f09d547e580>>
Traceback (most recent call last):
  File "/opt/ros/noetic/lib/python3/dist-packages/rospy/topics.py", line 750, in _invoke_callback
    cb(msg)
  File "./train.py", line 139, in pose_array_callback
    self.global_start = msg.poses[0]
IndexError: list index out of range

[rosout][ERROR] 2020-11-29 08:19:14,475: bad callback: <bound method ROSNode.pose_array_callback of <__main__.ROSNode object at 0x7f09d547e580>>
Traceback (most recent call last):
  File "/opt/ros/noetic/lib/python3/dist-packages/rospy/topics.py", line 750, in _invoke_callback
    cb(msg)
  File "./train.py", line 139, in pose_array_callback
    self.global_start = msg.poses[0]
IndexError: list index out of range

[rosout][ERROR] 2020-11-29 08:19:14,486: bad callback: <bound method ROSNode.pose_array_callback of <__main__.ROSNode object at 0x7f09d547e580>>
Traceback (most recent call last):
  File "/opt/ros/noetic/lib/python3/dist-packages/rospy/topics.py", line 750, in _invoke_callback
    cb(msg)
  File "./train.py", line 139, in pose_array_callback
    self.global_start = msg.poses[0]
IndexError: list index out of range

[rosout][ERROR] 2020-11-29 08:19:14,497: bad callback: <bound method ROSNode.pose_array_callback of <__main__.ROSNode object at 0x7f09d547e580>>
Traceback (most recent call last):
  File "/opt/ros/noetic/lib/python3/dist-packages/rospy/topics.py", line 750, in _invoke_callback
    cb(msg)
  File "./train.py", line 139, in pose_array_callback
    self.global_start = msg.poses[0]
IndexError: list index out of range

[rosout][ERROR] 2020-11-29 08:19:14,506: bad callback: <bound method ROSNode.pose_array_callback of <__main__.ROSNode object at 0x7f09d547e580>>
Traceback (most recent call last):
  File "/opt/ros/noetic/lib/python3/dist-packages/rospy/topics.py", line 750, in _invoke_callback
    cb(msg)
  File "./train.py", line 139, in pose_array_callback
    self.global_start = msg.poses[0]
IndexError: list index out of range

[rosout][ERROR] 2020-11-29 08:19:14,517: bad callback: <bound method ROSNode.pose_array_callback of <__main__.ROSNode object at 0x7f09d547e580>>
Traceback (most recent call last):
  File "/opt/ros/noetic/lib/python3/dist-packages/rospy/topics.py", line 750, in _invoke_callback
    cb(msg)
  File "./train.py", line 139, in pose_array_callback
    self.global_start = msg.poses[0]
IndexError: list index out of range

[rosout][ERROR] 2020-11-29 08:19:14,527: bad callback: <bound method ROSNode.pose_array_callback of <__main__.ROSNode object at 0x7f09d547e580>>
Traceback (most recent call last):
  File "/opt/ros/noetic/lib/python3/dist-packages/rospy/topics.py", line 750, in _invoke_callback
    cb(msg)
  File "./train.py", line 139, in pose_array_callback
    self.global_start = msg.poses[0]
IndexError: list index out of range

[rosout][ERROR] 2020-11-29 08:19:14,537: bad callback: <bound method ROSNode.pose_array_callback of <__main__.ROSNode object at 0x7f09d547e580>>
Traceback (most recent call last):
  File "/opt/ros/noetic/lib/python3/dist-packages/rospy/topics.py", line 750, in _invoke_callback
    cb(msg)
  File "./train.py", line 139, in pose_array_callback
    self.global_start = msg.poses[0]
IndexError: list index out of range

[rosout][ERROR] 2020-11-29 08:19:14,546: bad callback: <bound method ROSNode.pose_array_callback of <__main__.ROSNode object at 0x7f09d547e580>>
Traceback (most recent call last):
  File "/opt/ros/noetic/lib/python3/dist-packages/rospy/topics.py", line 750, in _invoke_callback
    cb(msg)
  File "./train.py", line 139, in pose_array_callback
    self.global_start = msg.poses[0]
IndexError: list index out of range

[rosout][ERROR] 2020-11-29 08:19:14,557: bad callback: <bound method ROSNode.pose_array_callback of <__main__.ROSNode object at 0x7f09d547e580>>
Traceback (most recent call last):
  File "/opt/ros/noetic/lib/python3/dist-packages/rospy/topics.py", line 750, in _invoke_callback
    cb(msg)
  File "./train.py", line 139, in pose_array_callback
    self.global_start = msg.poses[0]
IndexError: list index out of range

[rosout][ERROR] 2020-11-29 08:19:14,566: bad callback: <bound method ROSNode.pose_array_callback of <__main__.ROSNode object at 0x7f09d547e580>>
Traceback (most recent call last):
  File "/opt/ros/noetic/lib/python3/dist-packages/rospy/topics.py", line 750, in _invoke_callback
    cb(msg)
  File "./train.py", line 139, in pose_array_callback
    self.global_start = msg.poses[0]
IndexError: list index out of range

[rosout][ERROR] 2020-11-29 08:19:14,577: bad callback: <bound method ROSNode.pose_array_callback of <__main__.ROSNode object at 0x7f09d547e580>>
Traceback (most recent call last):
  File "/opt/ros/noetic/lib/python3/dist-packages/rospy/topics.py", line 750, in _invoke_callback
    cb(msg)
  File "./train.py", line 139, in pose_array_callback
    self.global_start = msg.poses[0]
IndexError: list index out of range

[rosout][ERROR] 2020-11-29 08:19:14,587: bad callback: <bound method ROSNode.pose_array_callback of <__main__.ROSNode object at 0x7f09d547e580>>
Traceback (most recent call last):
  File "/opt/ros/noetic/lib/python3/dist-packages/rospy/topics.py", line 750, in _invoke_callback
    cb(msg)
  File "./train.py", line 139, in pose_array_callback
    self.global_start = msg.poses[0]
IndexError: list index out of range

[rosout][ERROR] 2020-11-29 08:19:14,596: bad callback: <bound method ROSNode.pose_array_callback of <__main__.ROSNode object at 0x7f09d547e580>>
Traceback (most recent call last):
  File "/opt/ros/noetic/lib/python3/dist-packages/rospy/topics.py", line 750, in _invoke_callback
    cb(msg)
  File "./train.py", line 139, in pose_array_callback
    self.global_start = msg.poses[0]
IndexError: list index out of range

[rosout][ERROR] 2020-11-29 08:19:14,607: bad callback: <bound method ROSNode.pose_array_callback of <__main__.ROSNode object at 0x7f09d547e580>>
Traceback (most recent call last):
  File "/opt/ros/noetic/lib/python3/dist-packages/rospy/topics.py", line 750, in _invoke_callback
    cb(msg)
  File "./train.py", line 139, in pose_array_callback
    self.global_start = msg.poses[0]
IndexError: list index out of range

[rosout][ERROR] 2020-11-29 08:19:14,616: bad callback: <bound method ROSNode.pose_array_callback of <__main__.ROSNode object at 0x7f09d547e580>>
Traceback (most recent call last):
  File "/opt/ros/noetic/lib/python3/dist-packages/rospy/topics.py", line 750, in _invoke_callback
    cb(msg)
  File "./train.py", line 139, in pose_array_callback
    self.global_start = msg.poses[0]
IndexError: list index out of range

[rosout][ERROR] 2020-11-29 08:19:14,627: bad callback: <bound method ROSNode.pose_array_callback of <__main__.ROSNode object at 0x7f09d547e580>>
Traceback (most recent call last):
  File "/opt/ros/noetic/lib/python3/dist-packages/rospy/topics.py", line 750, in _invoke_callback
    cb(msg)
  File "./train.py", line 139, in pose_array_callback
    self.global_start = msg.poses[0]
IndexError: list index out of range

[rosout][ERROR] 2020-11-29 08:19:14,636: bad callback: <bound method ROSNode.pose_array_callback of <__main__.ROSNode object at 0x7f09d547e580>>
Traceback (most recent call last):
  File "/opt/ros/noetic/lib/python3/dist-packages/rospy/topics.py", line 750, in _invoke_callback
    cb(msg)
  File "./train.py", line 139, in pose_array_callback
    self.global_start = msg.poses[0]
IndexError: list index out of range

[rosout][ERROR] 2020-11-29 08:19:14,646: bad callback: <bound method ROSNode.pose_array_callback of <__main__.ROSNode object at 0x7f09d547e580>>
Traceback (most recent call last):
  File "/opt/ros/noetic/lib/python3/dist-packages/rospy/topics.py", line 750, in _invoke_callback
    cb(msg)
  File "./train.py", line 139, in pose_array_callback
    self.global_start = msg.poses[0]
IndexError: list index out of range

[rosout][ERROR] 2020-11-29 08:19:14,656: bad callback: <bound method ROSNode.pose_array_callback of <__main__.ROSNode object at 0x7f09d547e580>>
Traceback (most recent call last):
  File "/opt/ros/noetic/lib/python3/dist-packages/rospy/topics.py", line 750, in _invoke_callback
    cb(msg)
  File "./train.py", line 139, in pose_array_callback
    self.global_start = msg.poses[0]
IndexError: list index out of range

[rosout][ERROR] 2020-11-29 08:19:14,666: bad callback: <bound method ROSNode.pose_array_callback of <__main__.ROSNode object at 0x7f09d547e580>>
Traceback (most recent call last):
  File "/opt/ros/noetic/lib/python3/dist-packages/rospy/topics.py", line 750, in _invoke_callback
    cb(msg)
  File "./train.py", line 139, in pose_array_callback
    self.global_start = msg.poses[0]
IndexError: list index out of range

[rosout][ERROR] 2020-11-29 08:19:14,677: bad callback: <bound method ROSNode.pose_array_callback of <__main__.ROSNode object at 0x7f09d547e580>>
Traceback (most recent call last):
  File "/opt/ros/noetic/lib/python3/dist-packages/rospy/topics.py", line 750, in _invoke_callback
    cb(msg)
  File "./train.py", line 139, in pose_array_callback
    self.global_start = msg.poses[0]
IndexError: list index out of range

[rosout][ERROR] 2020-11-29 08:19:14,686: bad callback: <bound method ROSNode.pose_array_callback of <__main__.ROSNode object at 0x7f09d547e580>>
Traceback (most recent call last):
  File "/opt/ros/noetic/lib/python3/dist-packages/rospy/topics.py", line 750, in _invoke_callback
    cb(msg)
  File "./train.py", line 139, in pose_array_callback
    self.global_start = msg.poses[0]
IndexError: list index out of range

[rosout][ERROR] 2020-11-29 08:19:14,696: bad callback: <bound method ROSNode.pose_array_callback of <__main__.ROSNode object at 0x7f09d547e580>>
Traceback (most recent call last):
  File "/opt/ros/noetic/lib/python3/dist-packages/rospy/topics.py", line 750, in _invoke_callback
    cb(msg)
  File "./train.py", line 139, in pose_array_callback
    self.global_start = msg.poses[0]
IndexError: list index out of range

[rosout][ERROR] 2020-11-29 08:19:14,706: bad callback: <bound method ROSNode.pose_array_callback of <__main__.ROSNode object at 0x7f09d547e580>>
Traceback (most recent call last):
  File "/opt/ros/noetic/lib/python3/dist-packages/rospy/topics.py", line 750, in _invoke_callback
    cb(msg)
  File "./train.py", line 139, in pose_array_callback
    self.global_start = msg.poses[0]
IndexError: list index out of range

[rosout][ERROR] 2020-11-29 08:19:14,716: bad callback: <bound method ROSNode.pose_array_callback of <__main__.ROSNode object at 0x7f09d547e580>>
Traceback (most recent call last):
  File "/opt/ros/noetic/lib/python3/dist-packages/rospy/topics.py", line 750, in _invoke_callback
    cb(msg)
  File "./train.py", line 139, in pose_array_callback
    self.global_start = msg.poses[0]
IndexError: list index out of range

[rosout][ERROR] 2020-11-29 08:19:14,726: bad callback: <bound method ROSNode.pose_array_callback of <__main__.ROSNode object at 0x7f09d547e580>>
Traceback (most recent call last):
  File "/opt/ros/noetic/lib/python3/dist-packages/rospy/topics.py", line 750, in _invoke_callback
    cb(msg)
  File "./train.py", line 139, in pose_array_callback
    self.global_start = msg.poses[0]
IndexError: list index out of range

[rosout][ERROR] 2020-11-29 08:19:14,736: bad callback: <bound method ROSNode.pose_array_callback of <__main__.ROSNode object at 0x7f09d547e580>>
Traceback (most recent call last):
  File "/opt/ros/noetic/lib/python3/dist-packages/rospy/topics.py", line 750, in _invoke_callback
    cb(msg)
  File "./train.py", line 139, in pose_array_callback
    self.global_start = msg.poses[0]
IndexError: list index out of range

[rosout][ERROR] 2020-11-29 08:19:14,746: bad callback: <bound method ROSNode.pose_array_callback of <__main__.ROSNode object at 0x7f09d547e580>>
Traceback (most recent call last):
  File "/opt/ros/noetic/lib/python3/dist-packages/rospy/topics.py", line 750, in _invoke_callback
    cb(msg)
  File "./train.py", line 139, in pose_array_callback
    self.global_start = msg.poses[0]
IndexError: list index out of range

[rosout][ERROR] 2020-11-29 08:19:14,756: bad callback: <bound method ROSNode.pose_array_callback of <__main__.ROSNode object at 0x7f09d547e580>>
Traceback (most recent call last):
  File "/opt/ros/noetic/lib/python3/dist-packages/rospy/topics.py", line 750, in _invoke_callback
    cb(msg)
  File "./train.py", line 139, in pose_array_callback
    self.global_start = msg.poses[0]
IndexError: list index out of range

[rosout][ERROR] 2020-11-29 08:19:14,766: bad callback: <bound method ROSNode.pose_array_callback of <__main__.ROSNode object at 0x7f09d547e580>>
Traceback (most recent call last):
  File "/opt/ros/noetic/lib/python3/dist-packages/rospy/topics.py", line 750, in _invoke_callback
    cb(msg)
  File "./train.py", line 139, in pose_array_callback
    self.global_start = msg.poses[0]
IndexError: list index out of range

[rosout][ERROR] 2020-11-29 08:19:14,776: bad callback: <bound method ROSNode.pose_array_callback of <__main__.ROSNode object at 0x7f09d547e580>>
Traceback (most recent call last):
  File "/opt/ros/noetic/lib/python3/dist-packages/rospy/topics.py", line 750, in _invoke_callback
    cb(msg)
  File "./train.py", line 139, in pose_array_callback
    self.global_start = msg.poses[0]
IndexError: list index out of range

[rosout][ERROR] 2020-11-29 08:19:14,786: bad callback: <bound method ROSNode.pose_array_callback of <__main__.ROSNode object at 0x7f09d547e580>>
Traceback (most recent call last):
  File "/opt/ros/noetic/lib/python3/dist-packages/rospy/topics.py", line 750, in _invoke_callback
    cb(msg)
  File "./train.py", line 139, in pose_array_callback
    self.global_start = msg.poses[0]
IndexError: list index out of range

[rosout][ERROR] 2020-11-29 08:19:14,796: bad callback: <bound method ROSNode.pose_array_callback of <__main__.ROSNode object at 0x7f09d547e580>>
Traceback (most recent call last):
  File "/opt/ros/noetic/lib/python3/dist-packages/rospy/topics.py", line 750, in _invoke_callback
    cb(msg)
  File "./train.py", line 139, in pose_array_callback
    self.global_start = msg.poses[0]
IndexError: list index out of range

[rosout][ERROR] 2020-11-29 08:19:14,806: bad callback: <bound method ROSNode.pose_array_callback of <__main__.ROSNode object at 0x7f09d547e580>>
Traceback (most recent call last):
  File "/opt/ros/noetic/lib/python3/dist-packages/rospy/topics.py", line 750, in _invoke_callback
    cb(msg)
  File "./train.py", line 139, in pose_array_callback
    self.global_start = msg.poses[0]
IndexError: list index out of range

[rosout][ERROR] 2020-11-29 08:19:14,816: bad callback: <bound method ROSNode.pose_array_callback of <__main__.ROSNode object at 0x7f09d547e580>>
Traceback (most recent call last):
  File "/opt/ros/noetic/lib/python3/dist-packages/rospy/topics.py", line 750, in _invoke_callback
    cb(msg)
  File "./train.py", line 139, in pose_array_callback
    self.global_start = msg.poses[0]
IndexError: list index out of range

[rosout][ERROR] 2020-11-29 08:19:14,826: bad callback: <bound method ROSNode.pose_array_callback of <__main__.ROSNode object at 0x7f09d547e580>>
Traceback (most recent call last):
  File "/opt/ros/noetic/lib/python3/dist-packages/rospy/topics.py", line 750, in _invoke_callback
    cb(msg)
  File "./train.py", line 139, in pose_array_callback
    self.global_start = msg.poses[0]
IndexError: list index out of range

[rosout][ERROR] 2020-11-29 08:19:14,836: bad callback: <bound method ROSNode.pose_array_callback of <__main__.ROSNode object at 0x7f09d547e580>>
Traceback (most recent call last):
  File "/opt/ros/noetic/lib/python3/dist-packages/rospy/topics.py", line 750, in _invoke_callback
    cb(msg)
  File "./train.py", line 139, in pose_array_callback
    self.global_start = msg.poses[0]
IndexError: list index out of range

[rosout][ERROR] 2020-11-29 08:19:14,846: bad callback: <bound method ROSNode.pose_array_callback of <__main__.ROSNode object at 0x7f09d547e580>>
Traceback (most recent call last):
  File "/opt/ros/noetic/lib/python3/dist-packages/rospy/topics.py", line 750, in _invoke_callback
    cb(msg)
  File "./train.py", line 139, in pose_array_callback
    self.global_start = msg.poses[0]
IndexError: list index out of range

[rosout][ERROR] 2020-11-29 08:19:14,856: bad callback: <bound method ROSNode.pose_array_callback of <__main__.ROSNode object at 0x7f09d547e580>>
Traceback (most recent call last):
  File "/opt/ros/noetic/lib/python3/dist-packages/rospy/topics.py", line 750, in _invoke_callback
    cb(msg)
  File "./train.py", line 139, in pose_array_callback
    self.global_start = msg.poses[0]
IndexError: list index out of range

[rosout][ERROR] 2020-11-29 08:19:14,866: bad callback: <bound method ROSNode.pose_array_callback of <__main__.ROSNode object at 0x7f09d547e580>>
Traceback (most recent call last):
  File "/opt/ros/noetic/lib/python3/dist-packages/rospy/topics.py", line 750, in _invoke_callback
    cb(msg)
  File "./train.py", line 139, in pose_array_callback
    self.global_start = msg.poses[0]
IndexError: list index out of range

[rosout][ERROR] 2020-11-29 08:19:14,876: bad callback: <bound method ROSNode.pose_array_callback of <__main__.ROSNode object at 0x7f09d547e580>>
Traceback (most recent call last):
  File "/opt/ros/noetic/lib/python3/dist-packages/rospy/topics.py", line 750, in _invoke_callback
    cb(msg)
  File "./train.py", line 139, in pose_array_callback
    self.global_start = msg.poses[0]
IndexError: list index out of range

[rosout][ERROR] 2020-11-29 08:19:14,886: bad callback: <bound method ROSNode.pose_array_callback of <__main__.ROSNode object at 0x7f09d547e580>>
Traceback (most recent call last):
  File "/opt/ros/noetic/lib/python3/dist-packages/rospy/topics.py", line 750, in _invoke_callback
    cb(msg)
  File "./train.py", line 139, in pose_array_callback
    self.global_start = msg.poses[0]
IndexError: list index out of range

[rosout][ERROR] 2020-11-29 08:19:14,896: bad callback: <bound method ROSNode.pose_array_callback of <__main__.ROSNode object at 0x7f09d547e580>>
Traceback (most recent call last):
  File "/opt/ros/noetic/lib/python3/dist-packages/rospy/topics.py", line 750, in _invoke_callback
    cb(msg)
  File "./train.py", line 139, in pose_array_callback
    self.global_start = msg.poses[0]
IndexError: list index out of range

[rosout][ERROR] 2020-11-29 08:19:14,906: bad callback: <bound method ROSNode.pose_array_callback of <__main__.ROSNode object at 0x7f09d547e580>>
Traceback (most recent call last):
  File "/opt/ros/noetic/lib/python3/dist-packages/rospy/topics.py", line 750, in _invoke_callback
    cb(msg)
  File "./train.py", line 139, in pose_array_callback
    self.global_start = msg.poses[0]
IndexError: list index out of range

[rosout][ERROR] 2020-11-29 08:19:14,916: bad callback: <bound method ROSNode.pose_array_callback of <__main__.ROSNode object at 0x7f09d547e580>>
Traceback (most recent call last):
  File "/opt/ros/noetic/lib/python3/dist-packages/rospy/topics.py", line 750, in _invoke_callback
    cb(msg)
  File "./train.py", line 139, in pose_array_callback
    self.global_start = msg.poses[0]
IndexError: list index out of range

[rosout][ERROR] 2020-11-29 08:19:14,926: bad callback: <bound method ROSNode.pose_array_callback of <__main__.ROSNode object at 0x7f09d547e580>>
Traceback (most recent call last):
  File "/opt/ros/noetic/lib/python3/dist-packages/rospy/topics.py", line 750, in _invoke_callback
    cb(msg)
  File "./train.py", line 139, in pose_array_callback
    self.global_start = msg.poses[0]
IndexError: list index out of range

[rosout][ERROR] 2020-11-29 08:19:14,936: bad callback: <bound method ROSNode.pose_array_callback of <__main__.ROSNode object at 0x7f09d547e580>>
Traceback (most recent call last):
  File "/opt/ros/noetic/lib/python3/dist-packages/rospy/topics.py", line 750, in _invoke_callback
    cb(msg)
  File "./train.py", line 139, in pose_array_callback
    self.global_start = msg.poses[0]
IndexError: list index out of range

[rosout][ERROR] 2020-11-29 08:19:14,946: bad callback: <bound method ROSNode.pose_array_callback of <__main__.ROSNode object at 0x7f09d547e580>>
Traceback (most recent call last):
  File "/opt/ros/noetic/lib/python3/dist-packages/rospy/topics.py", line 750, in _invoke_callback
    cb(msg)
  File "./train.py", line 139, in pose_array_callback
    self.global_start = msg.poses[0]
IndexError: list index out of range

[rosout][ERROR] 2020-11-29 08:19:14,956: bad callback: <bound method ROSNode.pose_array_callback of <__main__.ROSNode object at 0x7f09d547e580>>
Traceback (most recent call last):
  File "/opt/ros/noetic/lib/python3/dist-packages/rospy/topics.py", line 750, in _invoke_callback
    cb(msg)
  File "./train.py", line 139, in pose_array_callback
    self.global_start = msg.poses[0]
IndexError: list index out of range

[rosout][ERROR] 2020-11-29 08:19:14,967: bad callback: <bound method ROSNode.pose_array_callback of <__main__.ROSNode object at 0x7f09d547e580>>
Traceback (most recent call last):
  File "/opt/ros/noetic/lib/python3/dist-packages/rospy/topics.py", line 750, in _invoke_callback
    cb(msg)
  File "./train.py", line 139, in pose_array_callback
    self.global_start = msg.poses[0]
IndexError: list index out of range

[rosout][ERROR] 2020-11-29 08:19:14,976: bad callback: <bound method ROSNode.pose_array_callback of <__main__.ROSNode object at 0x7f09d547e580>>
Traceback (most recent call last):
  File "/opt/ros/noetic/lib/python3/dist-packages/rospy/topics.py", line 750, in _invoke_callback
    cb(msg)
  File "./train.py", line 139, in pose_array_callback
    self.global_start = msg.poses[0]
IndexError: list index out of range

[rosout][ERROR] 2020-11-29 08:19:14,986: bad callback: <bound method ROSNode.pose_array_callback of <__main__.ROSNode object at 0x7f09d547e580>>
Traceback (most recent call last):
  File "/opt/ros/noetic/lib/python3/dist-packages/rospy/topics.py", line 750, in _invoke_callback
    cb(msg)
  File "./train.py", line 139, in pose_array_callback
    self.global_start = msg.poses[0]
IndexError: list index out of range

[rosout][ERROR] 2020-11-29 08:19:14,997: bad callback: <bound method ROSNode.pose_array_callback of <__main__.ROSNode object at 0x7f09d547e580>>
Traceback (most recent call last):
  File "/opt/ros/noetic/lib/python3/dist-packages/rospy/topics.py", line 750, in _invoke_callback
    cb(msg)
  File "./train.py", line 139, in pose_array_callback
    self.global_start = msg.poses[0]
IndexError: list index out of range

[rosout][ERROR] 2020-11-29 08:19:15,007: bad callback: <bound method ROSNode.pose_array_callback of <__main__.ROSNode object at 0x7f09d547e580>>
Traceback (most recent call last):
  File "/opt/ros/noetic/lib/python3/dist-packages/rospy/topics.py", line 750, in _invoke_callback
    cb(msg)
  File "./train.py", line 139, in pose_array_callback
    self.global_start = msg.poses[0]
IndexError: list index out of range

[rosout][ERROR] 2020-11-29 08:19:15,017: bad callback: <bound method ROSNode.pose_array_callback of <__main__.ROSNode object at 0x7f09d547e580>>
Traceback (most recent call last):
  File "/opt/ros/noetic/lib/python3/dist-packages/rospy/topics.py", line 750, in _invoke_callback
    cb(msg)
  File "./train.py", line 139, in pose_array_callback
    self.global_start = msg.poses[0]
IndexError: list index out of range

[rosout][ERROR] 2020-11-29 08:19:15,026: bad callback: <bound method ROSNode.pose_array_callback of <__main__.ROSNode object at 0x7f09d547e580>>
Traceback (most recent call last):
  File "/opt/ros/noetic/lib/python3/dist-packages/rospy/topics.py", line 750, in _invoke_callback
    cb(msg)
  File "./train.py", line 139, in pose_array_callback
    self.global_start = msg.poses[0]
IndexError: list index out of range

[rosout][ERROR] 2020-11-29 08:19:15,037: bad callback: <bound method ROSNode.pose_array_callback of <__main__.ROSNode object at 0x7f09d547e580>>
Traceback (most recent call last):
  File "/opt/ros/noetic/lib/python3/dist-packages/rospy/topics.py", line 750, in _invoke_callback
    cb(msg)
  File "./train.py", line 139, in pose_array_callback
    self.global_start = msg.poses[0]
IndexError: list index out of range

[rosout][ERROR] 2020-11-29 08:19:15,046: bad callback: <bound method ROSNode.pose_array_callback of <__main__.ROSNode object at 0x7f09d547e580>>
Traceback (most recent call last):
  File "/opt/ros/noetic/lib/python3/dist-packages/rospy/topics.py", line 750, in _invoke_callback
    cb(msg)
  File "./train.py", line 139, in pose_array_callback
    self.global_start = msg.poses[0]
IndexError: list index out of range

[rosout][ERROR] 2020-11-29 08:19:15,057: bad callback: <bound method ROSNode.pose_array_callback of <__main__.ROSNode object at 0x7f09d547e580>>
Traceback (most recent call last):
  File "/opt/ros/noetic/lib/python3/dist-packages/rospy/topics.py", line 750, in _invoke_callback
    cb(msg)
  File "./train.py", line 139, in pose_array_callback
    self.global_start = msg.poses[0]
IndexError: list index out of range

[rosout][ERROR] 2020-11-29 08:19:15,066: bad callback: <bound method ROSNode.pose_array_callback of <__main__.ROSNode object at 0x7f09d547e580>>
Traceback (most recent call last):
  File "/opt/ros/noetic/lib/python3/dist-packages/rospy/topics.py", line 750, in _invoke_callback
    cb(msg)
  File "./train.py", line 139, in pose_array_callback
    self.global_start = msg.poses[0]
IndexError: list index out of range

[rosout][ERROR] 2020-11-29 08:19:15,076: bad callback: <bound method ROSNode.pose_array_callback of <__main__.ROSNode object at 0x7f09d547e580>>
Traceback (most recent call last):
  File "/opt/ros/noetic/lib/python3/dist-packages/rospy/topics.py", line 750, in _invoke_callback
    cb(msg)
  File "./train.py", line 139, in pose_array_callback
    self.global_start = msg.poses[0]
IndexError: list index out of range

[rosout][ERROR] 2020-11-29 08:19:15,087: bad callback: <bound method ROSNode.pose_array_callback of <__main__.ROSNode object at 0x7f09d547e580>>
Traceback (most recent call last):
  File "/opt/ros/noetic/lib/python3/dist-packages/rospy/topics.py", line 750, in _invoke_callback
    cb(msg)
  File "./train.py", line 139, in pose_array_callback
    self.global_start = msg.poses[0]
IndexError: list index out of range

[rosout][ERROR] 2020-11-29 08:19:15,097: bad callback: <bound method ROSNode.pose_array_callback of <__main__.ROSNode object at 0x7f09d547e580>>
Traceback (most recent call last):
  File "/opt/ros/noetic/lib/python3/dist-packages/rospy/topics.py", line 750, in _invoke_callback
    cb(msg)
  File "./train.py", line 139, in pose_array_callback
    self.global_start = msg.poses[0]
IndexError: list index out of range

[rosout][ERROR] 2020-11-29 08:19:15,107: bad callback: <bound method ROSNode.pose_array_callback of <__main__.ROSNode object at 0x7f09d547e580>>
Traceback (most recent call last):
  File "/opt/ros/noetic/lib/python3/dist-packages/rospy/topics.py", line 750, in _invoke_callback
    cb(msg)
  File "./train.py", line 139, in pose_array_callback
    self.global_start = msg.poses[0]
IndexError: list index out of range

[rosout][ERROR] 2020-11-29 08:19:15,116: bad callback: <bound method ROSNode.pose_array_callback of <__main__.ROSNode object at 0x7f09d547e580>>
Traceback (most recent call last):
  File "/opt/ros/noetic/lib/python3/dist-packages/rospy/topics.py", line 750, in _invoke_callback
    cb(msg)
  File "./train.py", line 139, in pose_array_callback
    self.global_start = msg.poses[0]
IndexError: list index out of range

[rosout][ERROR] 2020-11-29 08:19:15,127: bad callback: <bound method ROSNode.pose_array_callback of <__main__.ROSNode object at 0x7f09d547e580>>
Traceback (most recent call last):
  File "/opt/ros/noetic/lib/python3/dist-packages/rospy/topics.py", line 750, in _invoke_callback
    cb(msg)
  File "./train.py", line 139, in pose_array_callback
    self.global_start = msg.poses[0]
IndexError: list index out of range

[rosout][ERROR] 2020-11-29 08:19:15,137: bad callback: <bound method ROSNode.pose_array_callback of <__main__.ROSNode object at 0x7f09d547e580>>
Traceback (most recent call last):
  File "/opt/ros/noetic/lib/python3/dist-packages/rospy/topics.py", line 750, in _invoke_callback
    cb(msg)
  File "./train.py", line 139, in pose_array_callback
    self.global_start = msg.poses[0]
IndexError: list index out of range

[rosout][ERROR] 2020-11-29 08:19:15,147: bad callback: <bound method ROSNode.pose_array_callback of <__main__.ROSNode object at 0x7f09d547e580>>
Traceback (most recent call last):
  File "/opt/ros/noetic/lib/python3/dist-packages/rospy/topics.py", line 750, in _invoke_callback
    cb(msg)
  File "./train.py", line 139, in pose_array_callback
    self.global_start = msg.poses[0]
IndexError: list index out of range

[rosout][ERROR] 2020-11-29 08:19:15,157: bad callback: <bound method ROSNode.pose_array_callback of <__main__.ROSNode object at 0x7f09d547e580>>
Traceback (most recent call last):
  File "/opt/ros/noetic/lib/python3/dist-packages/rospy/topics.py", line 750, in _invoke_callback
    cb(msg)
  File "./train.py", line 139, in pose_array_callback
    self.global_start = msg.poses[0]
IndexError: list index out of range

[rosout][ERROR] 2020-11-29 08:19:15,166: bad callback: <bound method ROSNode.pose_array_callback of <__main__.ROSNode object at 0x7f09d547e580>>
Traceback (most recent call last):
  File "/opt/ros/noetic/lib/python3/dist-packages/rospy/topics.py", line 750, in _invoke_callback
    cb(msg)
  File "./train.py", line 139, in pose_array_callback
    self.global_start = msg.poses[0]
IndexError: list index out of range

[rosout][ERROR] 2020-11-29 08:19:15,177: bad callback: <bound method ROSNode.pose_array_callback of <__main__.ROSNode object at 0x7f09d547e580>>
Traceback (most recent call last):
  File "/opt/ros/noetic/lib/python3/dist-packages/rospy/topics.py", line 750, in _invoke_callback
    cb(msg)
  File "./train.py", line 139, in pose_array_callback
    self.global_start = msg.poses[0]
IndexError: list index out of range

[rosout][ERROR] 2020-11-29 08:19:15,187: bad callback: <bound method ROSNode.pose_array_callback of <__main__.ROSNode object at 0x7f09d547e580>>
Traceback (most recent call last):
  File "/opt/ros/noetic/lib/python3/dist-packages/rospy/topics.py", line 750, in _invoke_callback
    cb(msg)
  File "./train.py", line 139, in pose_array_callback
    self.global_start = msg.poses[0]
IndexError: list index out of range

[rosout][ERROR] 2020-11-29 08:19:15,197: bad callback: <bound method ROSNode.pose_array_callback of <__main__.ROSNode object at 0x7f09d547e580>>
Traceback (most recent call last):
  File "/opt/ros/noetic/lib/python3/dist-packages/rospy/topics.py", line 750, in _invoke_callback
    cb(msg)
  File "./train.py", line 139, in pose_array_callback
    self.global_start = msg.poses[0]
IndexError: list index out of range

[rosout][ERROR] 2020-11-29 08:19:15,207: bad callback: <bound method ROSNode.pose_array_callback of <__main__.ROSNode object at 0x7f09d547e580>>
Traceback (most recent call last):
  File "/opt/ros/noetic/lib/python3/dist-packages/rospy/topics.py", line 750, in _invoke_callback
    cb(msg)
  File "./train.py", line 139, in pose_array_callback
    self.global_start = msg.poses[0]
IndexError: list index out of range

[rosout][ERROR] 2020-11-29 08:19:15,218: bad callback: <bound method ROSNode.pose_array_callback of <__main__.ROSNode object at 0x7f09d547e580>>
Traceback (most recent call last):
  File "/opt/ros/noetic/lib/python3/dist-packages/rospy/topics.py", line 750, in _invoke_callback
    cb(msg)
  File "./train.py", line 139, in pose_array_callback
    self.global_start = msg.poses[0]
IndexError: list index out of range

[rosout][ERROR] 2020-11-29 08:19:15,227: bad callback: <bound method ROSNode.pose_array_callback of <__main__.ROSNode object at 0x7f09d547e580>>
Traceback (most recent call last):
  File "/opt/ros/noetic/lib/python3/dist-packages/rospy/topics.py", line 750, in _invoke_callback
    cb(msg)
  File "./train.py", line 139, in pose_array_callback
    self.global_start = msg.poses[0]
IndexError: list index out of range

[rosout][ERROR] 2020-11-29 08:19:15,238: bad callback: <bound method ROSNode.pose_array_callback of <__main__.ROSNode object at 0x7f09d547e580>>
Traceback (most recent call last):
  File "/opt/ros/noetic/lib/python3/dist-packages/rospy/topics.py", line 750, in _invoke_callback
    cb(msg)
  File "./train.py", line 139, in pose_array_callback
    self.global_start = msg.poses[0]
IndexError: list index out of range

[rosout][ERROR] 2020-11-29 08:19:15,247: bad callback: <bound method ROSNode.pose_array_callback of <__main__.ROSNode object at 0x7f09d547e580>>
Traceback (most recent call last):
  File "/opt/ros/noetic/lib/python3/dist-packages/rospy/topics.py", line 750, in _invoke_callback
    cb(msg)
  File "./train.py", line 139, in pose_array_callback
    self.global_start = msg.poses[0]
IndexError: list index out of range

[rosout][ERROR] 2020-11-29 08:19:15,258: bad callback: <bound method ROSNode.pose_array_callback of <__main__.ROSNode object at 0x7f09d547e580>>
Traceback (most recent call last):
  File "/opt/ros/noetic/lib/python3/dist-packages/rospy/topics.py", line 750, in _invoke_callback
    cb(msg)
  File "./train.py", line 139, in pose_array_callback
    self.global_start = msg.poses[0]
IndexError: list index out of range

[rosout][ERROR] 2020-11-29 08:19:15,268: bad callback: <bound method ROSNode.pose_array_callback of <__main__.ROSNode object at 0x7f09d547e580>>
Traceback (most recent call last):
  File "/opt/ros/noetic/lib/python3/dist-packages/rospy/topics.py", line 750, in _invoke_callback
    cb(msg)
  File "./train.py", line 139, in pose_array_callback
    self.global_start = msg.poses[0]
IndexError: list index out of range

[rosout][ERROR] 2020-11-29 08:19:15,277: bad callback: <bound method ROSNode.pose_array_callback of <__main__.ROSNode object at 0x7f09d547e580>>
Traceback (most recent call last):
  File "/opt/ros/noetic/lib/python3/dist-packages/rospy/topics.py", line 750, in _invoke_callback
    cb(msg)
  File "./train.py", line 139, in pose_array_callback
    self.global_start = msg.poses[0]
IndexError: list index out of range

[rosout][ERROR] 2020-11-29 08:19:15,288: bad callback: <bound method ROSNode.pose_array_callback of <__main__.ROSNode object at 0x7f09d547e580>>
Traceback (most recent call last):
  File "/opt/ros/noetic/lib/python3/dist-packages/rospy/topics.py", line 750, in _invoke_callback
    cb(msg)
  File "./train.py", line 139, in pose_array_callback
    self.global_start = msg.poses[0]
IndexError: list index out of range

[rosout][ERROR] 2020-11-29 08:19:15,297: bad callback: <bound method ROSNode.pose_array_callback of <__main__.ROSNode object at 0x7f09d547e580>>
Traceback (most recent call last):
  File "/opt/ros/noetic/lib/python3/dist-packages/rospy/topics.py", line 750, in _invoke_callback
    cb(msg)
  File "./train.py", line 139, in pose_array_callback
    self.global_start = msg.poses[0]
IndexError: list index out of range

[rosout][ERROR] 2020-11-29 08:19:15,308: bad callback: <bound method ROSNode.pose_array_callback of <__main__.ROSNode object at 0x7f09d547e580>>
Traceback (most recent call last):
  File "/opt/ros/noetic/lib/python3/dist-packages/rospy/topics.py", line 750, in _invoke_callback
    cb(msg)
  File "./train.py", line 139, in pose_array_callback
    self.global_start = msg.poses[0]
IndexError: list index out of range

[rosout][ERROR] 2020-11-29 08:19:15,318: bad callback: <bound method ROSNode.pose_array_callback of <__main__.ROSNode object at 0x7f09d547e580>>
Traceback (most recent call last):
  File "/opt/ros/noetic/lib/python3/dist-packages/rospy/topics.py", line 750, in _invoke_callback
    cb(msg)
  File "./train.py", line 139, in pose_array_callback
    self.global_start = msg.poses[0]
IndexError: list index out of range

[rosout][ERROR] 2020-11-29 08:19:15,327: bad callback: <bound method ROSNode.pose_array_callback of <__main__.ROSNode object at 0x7f09d547e580>>
Traceback (most recent call last):
  File "/opt/ros/noetic/lib/python3/dist-packages/rospy/topics.py", line 750, in _invoke_callback
    cb(msg)
  File "./train.py", line 139, in pose_array_callback
    self.global_start = msg.poses[0]
IndexError: list index out of range

[rosout][ERROR] 2020-11-29 08:19:15,338: bad callback: <bound method ROSNode.pose_array_callback of <__main__.ROSNode object at 0x7f09d547e580>>
Traceback (most recent call last):
  File "/opt/ros/noetic/lib/python3/dist-packages/rospy/topics.py", line 750, in _invoke_callback
    cb(msg)
  File "./train.py", line 139, in pose_array_callback
    self.global_start = msg.poses[0]
IndexError: list index out of range

[rospy.internal][INFO] 2020-11-29 08:19:18,048: topic[/scan] adding connection to [http://192.168.0.201:34681/], count 0
[rospy.internal][INFO] 2020-11-29 08:19:19,358: topic[/scan] adding connection to [http://192.168.0.201:39057/], count 1
[rospy.internal][INFO] 2020-11-29 08:19:19,363: topic[/bev/flow_image] adding connection to [http://192.168.0.201:32949/], count 0
[rospy.internal][INFO] 2020-11-29 08:19:19,367: topic[/bev/occupancy_image] adding connection to [http://192.168.0.201:32949/], count 0
[rospy.internal][INFO] 2020-11-29 08:19:19,593: topic[/cmd_vel] adding connection to [/bev_flow_estimator], count 0
[rospy.internal][INFO] 2020-11-29 08:19:19,978: topic[/odom] adding connection to [http://192.168.0.201:34681/], count 0
[rospy.internal][INFO] 2020-11-29 08:19:20,073: topic[/cmd_vel] adding connection to [/gazebo], count 1
[rospy.internal][WARNING] 2020-11-29 08:20:07,166: Unknown error initiating TCP/IP socket to 192.168.0.201:40209 (http://192.168.0.201:32949/): Traceback (most recent call last):
  File "/opt/ros/noetic/lib/python3/dist-packages/rospy/impl/tcpros_base.py", line 562, in connect
    self.read_header()
  File "/opt/ros/noetic/lib/python3/dist-packages/rospy/impl/tcpros_base.py", line 657, in read_header
    self._validate_header(read_ros_handshake_header(sock, self.read_buff, self.protocol.buff_size))
  File "/opt/ros/noetic/lib/python3/dist-packages/rosgraph/network.py", line 357, in read_ros_handshake_header
    d = sock.recv(buff_size)
ConnectionResetError: [Errno 104] Connection reset by peer

[rospy.internal][INFO] 2020-11-29 08:20:07,167: topic[/bev/flow_image] removing connection to http://192.168.0.201:32949/
[rospy.internal][WARNING] 2020-11-29 08:20:07,167: Unknown error initiating TCP/IP socket to 192.168.0.201:40209 (http://192.168.0.201:32949/): Traceback (most recent call last):
  File "/opt/ros/noetic/lib/python3/dist-packages/rospy/impl/tcpros_base.py", line 562, in connect
    self.read_header()
  File "/opt/ros/noetic/lib/python3/dist-packages/rospy/impl/tcpros_base.py", line 657, in read_header
    self._validate_header(read_ros_handshake_header(sock, self.read_buff, self.protocol.buff_size))
  File "/opt/ros/noetic/lib/python3/dist-packages/rosgraph/network.py", line 357, in read_ros_handshake_header
    d = sock.recv(buff_size)
ConnectionResetError: [Errno 104] Connection reset by peer

[rospy.internal][INFO] 2020-11-29 08:20:07,167: topic[/bev/occupancy_image] removing connection to http://192.168.0.201:32949/
[rospy.internal][INFO] 2020-11-29 08:20:07,498: topic[/cmd_vel] removing connection to /bev_flow_estimator
[rospy.internal][WARNING] 2020-11-29 08:21:47,374: Unknown error initiating TCP/IP socket to 192.168.0.201:46477 (http://192.168.0.201:39057/): Traceback (most recent call last):
  File "/opt/ros/noetic/lib/python3/dist-packages/rospy/impl/tcpros_base.py", line 562, in connect
    self.read_header()
  File "/opt/ros/noetic/lib/python3/dist-packages/rospy/impl/tcpros_base.py", line 657, in read_header
    self._validate_header(read_ros_handshake_header(sock, self.read_buff, self.protocol.buff_size))
  File "/opt/ros/noetic/lib/python3/dist-packages/rosgraph/network.py", line 357, in read_ros_handshake_header
    d = sock.recv(buff_size)
ConnectionResetError: [Errno 104] Connection reset by peer

[rospy.internal][INFO] 2020-11-29 08:21:47,374: topic[/scan] removing connection to http://192.168.0.201:39057/
[rospy.internal][INFO] 2020-11-29 08:21:49,346: topic[/scan] adding connection to [http://192.168.0.201:34443/], count 1
[rospy.internal][INFO] 2020-11-29 08:21:49,353: topic[/bev/flow_image] adding connection to [http://192.168.0.201:38673/], count 0
[rospy.internal][INFO] 2020-11-29 08:21:49,357: topic[/bev/occupancy_image] adding connection to [http://192.168.0.201:38673/], count 0
[rospy.internal][INFO] 2020-11-29 08:21:49,455: topic[/cmd_vel] adding connection to [/bev_flow_estimator], count 1
[rospy.core][INFO] 2020-11-29 08:25:01,040: signal_shutdown [atexit]
[rospy.internal][INFO] 2020-11-29 08:25:01,046: topic[/rosout] removing connection to /rosout
[rospy.internal][INFO] 2020-11-29 08:25:01,046: topic[/cmd_vel] removing connection to /gazebo
[rospy.internal][INFO] 2020-11-29 08:25:01,046: topic[/cmd_vel] removing connection to /bev_flow_estimator
[rospy.internal][INFO] 2020-11-29 08:25:01,047: topic[/episode_watcher/is_finish_episode] removing connection to /episode_manager
[rospy.internal][INFO] 2020-11-29 08:25:01,047: topic[/bev/flow_image] removing connection to http://192.168.0.201:38673/
[rospy.internal][INFO] 2020-11-29 08:25:01,048: topic[/bev/occupancy_image] removing connection to http://192.168.0.201:38673/
[rospy.internal][WARNING] 2020-11-29 08:25:01,049: Unknown error initiating TCP/IP socket to 192.168.0.201:45743 (http://192.168.0.201:38673/): Traceback (most recent call last):
  File "/opt/ros/noetic/lib/python3/dist-packages/rospy/impl/tcpros_base.py", line 562, in connect
    self.read_header()
  File "/opt/ros/noetic/lib/python3/dist-packages/rospy/impl/tcpros_base.py", line 657, in read_header
    self._validate_header(read_ros_handshake_header(sock, self.read_buff, self.protocol.buff_size))
AttributeError: 'NoneType' object has no attribute 'buff_size'

[rospy.internal][INFO] 2020-11-29 08:25:01,049: topic[/odom] removing connection to http://192.168.0.201:34681/
[rospy.internal][INFO] 2020-11-29 08:25:01,050: topic[/start_goal_points] removing connection to http://192.168.0.201:41767/
[rospy.internal][INFO] 2020-11-29 08:25:01,050: topic[/scan] removing connection to http://192.168.0.201:34681/
[rospy.internal][WARNING] 2020-11-29 08:25:01,051: Unknown error initiating TCP/IP socket to 192.168.0.201:39689 (http://192.168.0.201:34681/): Traceback (most recent call last):
  File "/opt/ros/noetic/lib/python3/dist-packages/rospy/impl/tcpros_base.py", line 562, in connect
    self.read_header()
  File "/opt/ros/noetic/lib/python3/dist-packages/rospy/impl/tcpros_base.py", line 657, in read_header
    self._validate_header(read_ros_handshake_header(sock, self.read_buff, self.protocol.buff_size))
AttributeError: 'NoneType' object has no attribute 'buff_size'

[rospy.internal][WARNING] 2020-11-29 08:25:01,051: Unknown error initiating TCP/IP socket to 192.168.0.201:33739 (http://192.168.0.201:41767/): Traceback (most recent call last):
  File "/opt/ros/noetic/lib/python3/dist-packages/rospy/impl/tcpros_base.py", line 562, in connect
    self.read_header()
  File "/opt/ros/noetic/lib/python3/dist-packages/rospy/impl/tcpros_base.py", line 657, in read_header
    self._validate_header(read_ros_handshake_header(sock, self.read_buff, self.protocol.buff_size))
AttributeError: 'NoneType' object has no attribute 'buff_size'

[rospy.internal][INFO] 2020-11-29 08:25:01,052: topic[/scan] removing connection to http://192.168.0.201:34443/
[rospy.internal][INFO] 2020-11-29 08:25:01,052: topic[/is_start_episode] removing connection to http://192.168.0.201:35281/
[rospy.internal][WARNING] 2020-11-29 08:25:01,053: Unknown error initiating TCP/IP socket to 192.168.0.201:32773 (http://192.168.0.201:34443/): Traceback (most recent call last):
  File "/opt/ros/noetic/lib/python3/dist-packages/rospy/impl/tcpros_base.py", line 562, in connect
    self.read_header()
  File "/opt/ros/noetic/lib/python3/dist-packages/rospy/impl/tcpros_base.py", line 657, in read_header
    self._validate_header(read_ros_handshake_header(sock, self.read_buff, self.protocol.buff_size))
AttributeError: 'NoneType' object has no attribute 'buff_size'

[rospy.impl.masterslave][INFO] 2020-11-29 08:25:01,053: atexit
